Workbook

Sheet BIODATA
A1: DATA NOMINASI SISWA KELAS XII
A2: SMKS PACET TAHUN AJARAN 2025/2026
A3: KURIKULUM MERDEKA
A6: Kab/Kota | C6: : | D6: Kabupaten Mojokerto
A7: Satuan Pendidikan | C7: : | D7: SMKS PACET
A8: Alamat/No. Telepon | C8: : | D8: Jl. Raya Pacet-Trawas No. 21, Ds. Pacet,Kec. Pacet,Kab. Mojokerto
A9: NPSN | C9: : | D9: 20549437
A10: Bidang Keahlian | C10: : | D10: Teknologi Manufaktur dan Rekayasa
A11: Program Keahlian | C11: : | D11: Tenik Otomotif
A12: Konsentrasi Keahlian | C12: : | D12: Teknik Kendaraan Ringan
A13: Tanggal Kelulusan | C13: : | D13: 04 Mei 2026
A14: Nama Kepala Sekolah | C14: : | D14: Moh Junaedi Hartanto, S.Pd
A15: NIP Kepala Sekolah | C15: : | D15: -
A16: Nama Pengawas | C16: : | D16: Arini Hidayati, S.Pd., M.Pd
A17: NIP Pengawas | C17: : | D17: 19761212 199802 2001
A18: Kepala Cabang Dinas | C18: : | D18: Pinky Hidayati, S.Psi., M.Psi.
A19: NIP Kepala Cabang Dinas | C19: : | D19: 19710101 200012 1 007
B20: 1 | C20: 2 | D20: 3 | F20: 4 | G20: 5 | H20: 6 | I20: 7 | J20: 8 | K20: 9 | L20: 10 | M20: 11 | N20: 12
A21: NO | B21: NIS | C21: NISN | D21: Nama Siswa | E21: Kelas | F21: Tempat dan Tgl Lahir | G21: Alamat rumah | H21: L/P | I21: Nama Orang Tua | J21: Ijazah terakhir | M21: Tanda Tangan Siswa | N21: Keterangan
J22: Asal sekolah | K22: No. Ijazah | L22: Tahun
A23: 1 | B23: 2 | C23: 3 | D23: 4 | E23: 5 | F23: 6 | G23: 7 | H23: 8 | I23: 9 | J23: 10 | K23: 11 | L23: 12 | M23: 13 | N23: 14
A24: 1 | D24: ABIL QOSHIM HAMDI | E24: X TKR 1 | H24: L
A25: 2 | D25: AHMA SELGI NUR SA'BAN | E25: X TKR 1 | H25: L
A26: 3 | D26: AHMAD ISOMUDDIN KHADIIQ | E26: X TKR 1 | H26: L
A27: 4 | D27: AHMAD VERNANDO ZAKARIA | E27: X TKR 1 | H27: L
A28: 5 | D28: ALVAREZA SETIA ANGGARA | E28: X TKR 1 | H28: L
A29: 6 | D29: ARSYAD ADITIA WIYONO | E29: X TKR 1 | H29: L
A30: 7 | D30: AULIYA ROHMAN AL BAIHAQI | E30: X TKR 1 | H30: L
A31: 8 | D31: AZIZUL HILMI FIRDAUS | E31: X TKR 1 | H31: L
A32: 9 | D32: DENILSEN ZAUSA OCTAVIANUS HERMANTO | E32: X TKR 1 | H32: L
A33: 10 | D33: FAJAR MAS'UD ALAMSYAH | E33: X TKR 1 | H33: L
A34: 11 | D34: JEFRI ALIF SUHENDRIK | E34: X TKR 1 | H34: L | L34: 2023
A35: 12 | D35: KRISNA DWI PUTRA | E35: X TKR 1 | H35: L
A36: 13 | D36: MARCELO JONAS NATRA ARSYAFIN | E36: X TKR 1 | H36: L
A37: 14 | D37: MOCHAMAD DWI ADISATRIO | E37: X TKR 1 | H37: L
A38: 15 | D38: MOHAMMAD BAMBANG SUBANDI | E38: X TKR 1 | H38: L
A39: 16 | D39: MOHAMMAD ILHAM ABDULLOH | E39: X TKR 1 | H39: L
A40: 17 | D40: MUHAMAD IQBAL LUCKY SAPUTRA | E40: X TKR 1 | H40: L
A41: 18 | D41: MUHAMMAD ARDIAN CAHYA PRADANA | E41: X TKR 1 | H41: L
A42: 19 | D42: MUHAMMAD MA'RUF ADI NUGRAHA | E42: X TKR 1 | H42: L
...

Sheet RR
A1: REKAP DATA NILAI RAPOR TP 2025/2026
A2: =BIODATA!D7 -> SMKS PACET
A5: NO | B5: NIS | C5: NISN | D5: NAMA | E5: L/P | F5: KELAS | G5: REKAP NILAI RAPOR
G6: Pendidikan Agama dan Budi Pekerti | M6: Pendidikan Pancasila | S6: Bahasa Indonesia | Y6: Pendidikan Jasmani , Olah Raga dan Kesehatan | AD6: Sejarah | AI6: Seni Budaya | AL6: Muatan Lokal ( Bahasa dan Sastra Jawa) | AR6: Matematika | AX6: Bahasa Inggris | BD6: Informatika | BG6: Projek Ilmu Pengetahuan Alam dan Sosial | BJ6: Dasar-Dasar Program Keahlian | BM6: Konsentrasi Keahlian | BQ6: Projek Kreatif dan Kewirausahaan | BU6: Pratik Kerja Lapangan | BW6: Mata Pelajaran pilihan | CA6: IPK
G7: SEMESTER | M7: SEMESTER | S7: SEMESTER | Y7: SEMESTER | AD7: SEMESTER | AI7: SEMESTER | AL7: SEMESTER | AR7: SEMESTER | AX7: SEMESTER | BD7: SEMESTER | BG7: SEMESTER | BJ7: SEMESTER | BM7: SEMESTER | BQ7: SEMESTER | BU7: SEMESTER | BW7: SEMESTER
G8: 1 | H8: 2 | I8: 3 | J8: 4 | K8: 5 | L8: Rata-rata | M8: 1 | N8: 2 | O8: 3 | P8: 4 | Q8: 5 | R8: Rata-rata | S8: 1 | T8: 2 | U8: 3 | V8: 4 | W8: 5 | X8: Rata-rata | Y8: 1 | Z8: 2 | AA8: 3 | AB8: 4 | AC8: Rata-rata | AD8: 1 | AE8: 2 | AF8: 3 | AG8: 4 | AH8: Rata-rata | AI8: 1 | AJ8: 2 | AK8: Rata-rata | AL8: 1 | AM8: 2 | AN8: 3 | AO8: 4 | AP8: 5 | AQ8: Rata-rata | AR8: 1 | AS8: 2 | AT8: 3 | AU8: 4 | AV8: 5 | AW8: Rata-rata | AX8: 1 | AY8: 2 | AZ8: 3 | BA8: 4 | BB8: 5 | BC8: Rata-rata | BD8: 1 | BE8: 2 | BF8: Rata-rata | BG8: 1 | BH8: 2 | BI8: Rata-rata | BJ8: 1 | BK8: 2 | BL8: Rata-rata | BM8: 3 | BN8: 4 | BO8: 5 | BP8: Rata-rata | BQ8: 3 | BR8: 4 | BS8: 5 | BT8: Rata-rata | BU8: 6 | BV8: Rata-rata | BW8: 3 | BX8: 4 | BY8: 5 | BZ8: Rata-rata
A9: 1 | B9: =BIODATA!B24 -> 0 | C9: =BIODATA!C24 -> 0 | D9: =BIODATA!D24 -> ABIL QOSHIM HAMDI | E9: =BIODATA!H24 -> L | F9: =BIODATA!E24 -> X TKR 1 | G9: 78 | L9: =AVERAGE(G9:K9) -> 78 | M9: 78 | R9: =AVERAGE(M9:Q9) -> 78 | S9: 80 | X9: =AVERAGE(S9:W9) -> 80 | Y9: 78 | AC9: =AVERAGE(Y9:AB9) -> 78 | AD9: 80 | AH9: =AVERAGE(AD9:AG9) -> 80 | AI9: 85 | AK9: =AVERAGE(AI9:AJ9) -> 85 | AL9: 78 | AQ9: =AVERAGE(AL9:AP9) -> 78 | AR9: 78 | AW9: =AVERAGE(AR9:AV9) -> 78 | AX9: 78 | BC9: =AVERAGE(AX9:BB9) -> 78 | BD9: 78 | BF9: =AVERAGE(BD9:BE9) -> 78 | BG9: 80 | BI9: =AVERAGE(BG9:BH9) -> 80 | BJ9: 78 | BL9: =AVERAGE(BJ9:BK9) -> 78 | BP9: =AVERAGE(BM9:BO9) -> #DIV/0! | BT9: =AVERAGE(BQ9:BS9) -> #DIV/0! | BV9: =BU9 -> 0 | BZ9: =AVERAGE(BW9:BY9) -> #DIV/0! | CA9: =IFERROR(ROUND(AVERAGE(L9,R9,X9,AC9,AH9,AK9,AQ9,AW9,BC9,BF9,BI9,BL9,BP9,BT9,BV9,BZ9),2),"")
A10: 2 | B10: =BIODATA!B25 -> 0 | C10: =BIODATA!C25 -> 0 | D10: =BIODATA!D25 -> AHMA SELGI NUR SA'BAN | E10: =BIODATA!H25 -> L | F10: =BIODATA!E25 -> X TKR 1 | G10: 85 | L10: =AVERAGE(G10:K10) -> 85 | M10: 78 | R10: =AVERAGE(M10:Q10) -> 78 | S10: 80 | X10: =AVERAGE(S10:W10) -> 80 | Y10: 88 | AC10: =AVERAGE(Y10:AB10) -> 88 | AD10: 87 | AH10: =AVERAGE(AD10:AG10) -> 87 | AI10: 85 | AK10: =AVERAGE(AI10:AJ10) -> 85 | AL10: 85 | AQ10: =AVERAGE(AL10:AP10) -> 85 | AR10: 79 | AW10: =AVERAGE(AR10:AV10) -> 79 | AX10: 80 | BC10: =AVERAGE(AX10:BB10) -> 80 | BD10: 78 | BF10: =AVERAGE(BD10:BE10) -> 78 | BG10: 82 | BI10: =AVERAGE(BG10:BH10) -> 82 | BJ10: 78 | BL10: =AVERAGE(BJ10:BK10) -> 78 | BP10: =AVERAGE(BM10:BO10) -> #DIV/0! | BT10: =AVERAGE(BQ10:BS10) -> #DIV/0! | BV10: =BU10 -> 0 | BZ10: =AVERAGE(BW10:BY10) -> #DIV/0! | CA10: =IFERROR(ROUND(AVERAGE(L10,R10,X10,AC10,AH10,AK10,AQ10,AW10,BC10,BF10,BI10,BL10,BP10,BT10,BV10,BZ10),2),"")
A11: 3 | B11: =BIODATA!B26 -> 0 | C11: =BIODATA!C26 -> 0 | D11: =BIODATA!D26 -> AHMAD ISOMUDDIN KHADIIQ | E11: =BIODATA!H26 -> L | F11: =BIODATA!E26 -> X TKR 1 | G11: 87 | L11: =AVERAGE(G11:K11) -> 87 | M11: 89 | R11: =AVERAGE(M11:Q11) -> 89 | S11: 80 | X11: =AVERAGE(S11:W11) -> 80 | Y11: 89 | AC11: =AVERAGE(Y11:AB11) -> 89 | AD11: 89 | AH11: =AVERAGE(AD11:AG11) -> 89 | AI11: 80 | AK11: =AVERAGE(AI11:AJ11) -> 80 | AL11: 87 | AQ11: =AVERAGE(AL11:AP11) -> 87 | AR11: 81 | AW11: =AVERAGE(AR11:AV11) -> 81 | AX11: 78 | BC11: =AVERAGE(AX11:BB11) -> 78 | BD11: 78 | BF11: =AVERAGE(BD11:BE11) -> 78 | BG11: 82 | BI11: =AVERAGE(BG11:BH11) -> 82 | BJ11: 78 | BL11: =AVERAGE(BJ11:BK11) -> 78 | BP11: =AVERAGE(BM11:BO11) -> #DIV/0! | BT11: =AVERAGE(BQ11:BS11) -> #DIV/0! | BV11: =BU11 -> 0 | BZ11: =AVERAGE(BW11:BY11) -> #DIV/0! | CA11: =IFERROR(ROUND(AVERAGE(L11,R11,X11,AC11,AH11,AK11,AQ11,AW11,BC11,BF11,BI11,BL11,BP11,BT11,BV11,BZ11),2),"")
A12: 4 | B12: =BIODATA!B27 -> 0 | C12: =BIODATA!C27 -> 0 | D12: =BIODATA!D27 -> AHMAD VERNANDO ZAKARIA | E12: =BIODATA!H27 -> L | F12: =BIODATA!E27 -> X TKR 1 | G12: 89 | L12: =AVERAGE(G12:K12) -> 89 | M12: 89 | R12: =AVERAGE(M12:Q12) -> 89 | S12: 82 | X12: =AVERAGE(S12:W12) -> 82 | Y12: 85 | AC12: =AVERAGE(Y12:AB12) -> 85 | AD12: 91 | AH12: =AVERAGE(AD12:AG12) -> 91 | AI12: 83 | AK12: =AVERAGE(AI12:AJ12) -> 83 | AL12: 89 | AQ12: =AVERAGE(AL12:AP12) -> 89 | AR12: 79 | AW12: =AVERAGE(AR12:AV12) -> 79 | AX12: 80 | BC12: =AVERAGE(AX12:BB12) -> 80 | BD12: 85 | BF12: =AVERAGE(BD12:BE12) -> 85 | BG12: 81 | BI12: =AVERAGE(BG12:BH12) -> 81 | BJ12: 85 | BL12: =AVERAGE(BJ12:BK12) -> 85 | BP12: =AVERAGE(BM12:BO12) -> #DIV/0! | BT12: =AVERAGE(BQ12:BS12) -> #DIV/0! | BV12: =BU12 -> 0 | BZ12: =AVERAGE(BW12:BY12) -> #DIV/0! | CA12: =IFERROR(ROUND(AVERAGE(L12,R12,X12,AC12,AH12,AK12,AQ12,AW12,BC12,BF12,BI12,BL12,BP12,BT12,BV12,BZ12),2),"")
A13: 5 | B13: =BIODATA!B28 -> 0 | C13: =BIODATA!C28 -> 0 | D13: =BIODATA!D28 -> ALVAREZA SETIA ANGGARA | E13: =BIODATA!H28 -> L | F13: =BIODATA!E28 -> X TKR 1 | G13: 85 | L13: =AVERAGE(G13:K13) -> 85 | M13: 78 | R13: =AVERAGE(M13:Q13) -> 78 | S13: 80 | X13: =AVERAGE(S13:W13) -> 80 | Y13: 86 | AC13: =AVERAGE(Y13:AB13) -> 86 | AD13: 87 | AH13: =AVERAGE(AD13:AG13) -> 87 | AI13: 85 | AK13: =AVERAGE(AI13:AJ13) -> 85 | AL13: 85 | AQ13: =AVERAGE(AL13:AP13) -> 85 | AR13: 79 | AW13: =AVERAGE(AR13:AV13) -> 79 | AX13: 82 | BC13: =AVERAGE(AX13:BB13) -> 82 | BD13: 88.333333 | BF13: =AVERAGE(BD13:BE13) -> 88.333333 | BG13: 81 | BI13: =AVERAGE(BG13:BH13) -> 81 | BJ13: 88.333333 | BL13: =AVERAGE(BJ13:BK13) -> 88.333333 | BP13: =AVERAGE(BM13:BO13) -> #DIV/0! | BT13: =AVERAGE(BQ13:BS13) -> #DIV/0! | BV13: =BU13 -> 0 | BZ13: =AVERAGE(BW13:BY13) -> #DIV/0! | CA13: =IFERROR(ROUND(AVERAGE(L13,R13,X13,AC13,AH13,AK13,AQ13,AW13,BC13,BF13,BI13,BL13,BP13,BT13,BV13,BZ13),2),"")
A14: 6 | B14: =BIODATA!B29 -> 0 | C14: =BIODATA!C29 -> 0 | D14: =BIODATA!D29 -> ARSYAD ADITIA WIYONO | E14: =BIODATA!H29 -> L | F14: =BIODATA!E29 -> X TKR 1 | G14: 83 | L14: =AVERAGE(G14:K14) -> 83 | M14: 88 | R14: =AVERAGE(M14:Q14) -> 88 | S14: 82 | X14: =AVERAGE(S14:W14) -> 82 | Y14: 87 | AC14: =AVERAGE(Y14:AB14) -> 87 | AD14: 85 | AH14: =AVERAGE(AD14:AG14) -> 85 | AI14: 80 | AK14: =AVERAGE(AI14:AJ14) -> 80 | AL14: 83 | AQ14: =AVERAGE(AL14:AP14) -> 83 | AR14: 80 | AW14: =AVERAGE(AR14:AV14) -> 80 | AX14: 78 | BC14: =AVERAGE(AX14:BB14) -> 78 | BD14: 82.666667 | BF14: =AVERAGE(BD14:BE14) -> 82.666667 | BG14: 81 | BI14: =AVERAGE(BG14:BH14) -> 81 | BJ14: 82.666667 | BL14: =AVERAGE(BJ14:BK14) -> 82.666667 | BP14: =AVERAGE(BM14:BO14) -> #DIV/0! | BT14: =AVERAGE(BQ14:BS14) -> #DIV/0! | BV14: =BU14 -> 0 | BZ14: =AVERAGE(BW14:BY14) -> #DIV/0! | CA14: =IFERROR(ROUND(AVERAGE(L14,R14,X14,AC14,AH14,AK14,AQ14,AW14,BC14,BF14,BI14,BL14,BP14,BT14,BV14,BZ14),2),"")
A15: 7 | B15: =BIODATA!B30 -> 0 | C15: =BIODATA!C30 -> 0 | D15: =BIODATA!D30 -> AULIYA ROHMAN AL BAIHAQI | E15: =BIODATA!H30 -> L | F15: =BIODATA!E30 -> X TKR 1 | G15: 84 | L15: =AVERAGE(G15:K15) -> 84 | M15: 78 | R15: =AVERAGE(M15:Q15) -> 78 | S15: 82 | X15: =AVERAGE(S15:W15) -> 82 | Y15: 89 | AC15: =AVERAGE(Y15:AB15) -> 89 | AD15: 86 | AH15: =AVERAGE(AD15:AG15) -> 86 | AI15: 80 | AK15: =AVERAGE(AI15:AJ15) -> 80 | AL15: 84 | AQ15: =AVERAGE(AL15:AP15) -> 84 | AR15: 80 | AW15: =AVERAGE(AR15:AV15) -> 80 | AX15: 79 | BC15: =AVERAGE(AX15:BB15) -> 79 | BD15: 78 | BF15: =AVERAGE(BD15:BE15) -> 78 | BG15: 81 | BI15: =AVERAGE(BG15:BH15) -> 81 | BJ15: 78 | BL15: =AVERAGE(BJ15:BK15) -> 78 | BP15: =AVERAGE(BM15:BO15) -> #DIV/0! | BT15: =AVERAGE(BQ15:BS15) -> #DIV/0! | BV15: =BU15 -> 0 | BZ15: =AVERAGE(BW15:BY15) -> #DIV/0! | CA15: =IFERROR(ROUND(AVERAGE(L15,R15,X15,AC15,AH15,AK15,AQ15,AW15,BC15,BF15,BI15,BL15,BP15,BT15,BV15,BZ15),2),"")
A16: 8 | B16: =BIODATA!B31 -> 0 | C16: =BIODATA!C31 -> 0 | D16: =BIODATA!D31 -> AZIZUL HILMI FIRDAUS | E16: =BIODATA!H31 -> L | F16: =BIODATA!E31 -> X TKR 1 | G16: 85 | L16: =AVERAGE(G16:K16) -> 85 | M16: 78 | R16: =AVERAGE(M16:Q16) -> 78 | S16: 82 | X16: =AVERAGE(S16:W16) -> 82 | Y16: 87 | AC16: =AVERAGE(Y16:AB16) -> 87 | AD16: 87 | AH16: =AVERAGE(AD16:AG16) -> 87 | AI16: 90 | AK16: =AVERAGE(AI16:AJ16) -> 90 | AL16: 85 | AQ16: =AVERAGE(AL16:AP16) -> 85 | AR16: 79 | AW16: =AVERAGE(AR16:AV16) -> 79 | AX16: 79 | BC16: =AVERAGE(AX16:BB16) -> 79 | BD16: 78 | BF16: =AVERAGE(BD16:BE16) -> 78 | BG16: 82 | BI16: =AVERAGE(BG16:BH16) -> 82 | BJ16: 78 | BL16: =AVERAGE(BJ16:BK16) -> 78 | BP16: =AVERAGE(BM16:BO16) -> #DIV/0! | BT16: =AVERAGE(BQ16:BS16) -> #DIV/0! | BV16: =BU16 -> 0 | BZ16: =AVERAGE(BW16:BY16) -> #DIV/0! | CA16: =IFERROR(ROUND(AVERAGE(L16,R16,X16,AC16,AH16,AK16,AQ16,AW16,BC16,BF16,BI16,BL16,BP16,BT16,BV16,BZ16),2),"")
A17: 9 | B17: =BIODATA!B32 -> 0 | C17: =BIODATA!C32 -> 0 | D17: =BIODATA!D32 -> DENILSEN ZAUSA OCTAVIANUS HERMANTO | E17: =BIODATA!H32 -> L | F17: =BIODATA!E32 -> X TKR 1 | G17: 80 | L17: =AVERAGE(G17:K17) -> 80 | M17: 78 | R17: =AVERAGE(M17:Q17) -> 78 | S17: 82 | X17: =AVERAGE(S17:W17) -> 82 | Y17: 88 | AC17: =AVERAGE(Y17:AB17) -> 88 | AD17: 82 | AH17: =AVERAGE(AD17:AG17) -> 82 | AI17: 85 | AK17: =AVERAGE(AI17:AJ17) -> 85 | AL17: 80 | AQ17: =AVERAGE(AL17:AP17) -> 80 | AR17: 79 | AW17: =AVERAGE(AR17:AV17) -> 79 | AX17: 80 | BC17: =AVERAGE(AX17:BB17) -> 80 | BD17: 78 | BF17: =AVERAGE(BD17:BE17) -> 78 | BG17: 82 | BI17: =AVERAGE(BG17:BH17) -> 82 | BJ17: 78 | BL17: =AVERAGE(BJ17:BK17) -> 78 | BP17: =AVERAGE(BM17:BO17) -> #DIV/0! | BT17: =AVERAGE(BQ17:BS17) -> #DIV/0! | BV17: =BU17 -> 0 | BZ17: =AVERAGE(BW17:BY17) -> #DIV/0! | CA17: =IFERROR(ROUND(AVERAGE(L17,R17,X17,AC17,AH17,AK17,AQ17,AW17,BC17,BF17,BI17,BL17,BP17,BT17,BV17,BZ17),2),"")
A18: 10 | B18: =BIODATA!B33 -> 0 | C18: =BIODATA!C33 -> 0 | D18: =BIODATA!D33 -> FAJAR MAS'UD ALAMSYAH | E18: =BIODATA!H33 -> L | F18: =BIODATA!E33 -> X TKR 1 | G18: 85 | L18: =AVERAGE(G18:K18) -> 85 | M18: 95 | R18: =AVERAGE(M18:Q18) -> 95 | S18: 80 | X18: =AVERAGE(S18:W18) -> 80 | Y18: 87 | AC18: =AVERAGE(Y18:AB18) -> 87 | AD18: 87 | AH18: =AVERAGE(AD18:AG18) -> 87 | AI18: 80 | AK18: =AVERAGE(AI18:AJ18) -> 80 | AL18: 85 | AQ18: =AVERAGE(AL18:AP18) -> 85 | AR18: 79 | AW18: =AVERAGE(AR18:AV18) -> 79 | AX18: 85 | BC18: =AVERAGE(AX18:BB18) -> 85 | BD18: 86.333333 | BF18: =AVERAGE(BD18:BE18) -> 86.333333 | BG18: 82 | BI18: =AVERAGE(BG18:BH18) -> 82 | BJ18: 86.333333 | BL18: =AVERAGE(BJ18:BK18) -> 86.333333 | BP18: =AVERAGE(BM18:BO18) -> #DIV/0! | BT18: =AVERAGE(BQ18:BS18) -> #DIV/0! | BV18: =BU18 -> 0 | BZ18: =AVERAGE(BW18:BY18) -> #DIV/0! | CA18: =IFERROR(ROUND(AVERAGE(L18,R18,X18,AC18,AH18,AK18,AQ18,AW18,BC18,BF18,BI18,BL18,BP18,BT18,BV18,BZ18),2),"")
A19: 11 | B19: =BIODATA!B34 -> 0 | C19: =BIODATA!C34 -> 0 | D19: =BIODATA!D34 -> JEFRI ALIF SUHENDRIK | E19: =BIODATA!H34 -> L | F19: =BIODATA!E34 -> X TKR 1 | L19: =AVERAGE(G19:K19) -> #DIV/0! | M19: 78 | R19: =AVERAGE(M19:Q19) -> 78 | S19: 81 | X19: =AVERAGE(S19:W19) -> 81 | Y19: 85 | AC19: =AVERAGE(Y19:AB19) -> 85 | AH19: =AVERAGE(AD19:AG19) -> #DIV/0! | AI19: 80 | AK19: =AVERAGE(AI19:AJ19) -> 80 | AQ19: =AVERAGE(AL19:AP19) -> #DIV/0! | AR19: 70 | AW19: =AVERAGE(AR19:AV19) -> 70 | AX19: 78 | BC19: =AVERAGE(AX19:BB19) -> 78 | BD19: 78 | BF19: =AVERAGE(BD19:BE19) -> 78 | BG19: 80 | BI19: =AVERAGE(BG19:BH19) -> 80 | BJ19: 78 | BL19: =AVERAGE(BJ19:BK19) -> 78 | BP19: =AVERAGE(BM19:BO19) -> #DIV/0! | BT19: =AVERAGE(BQ19:BS19) -> #DIV/0! | BV19: =BU19 -> 0 | BZ19: =AVERAGE(BW19:BY19) -> #DIV/0! | CA19: =IFERROR(ROUND(AVERAGE(L19,R19,X19,AC19,AH19,AK19,AQ19,AW19,BC19,BF19,BI19,BL19,BP19,BT19,BV19,BZ19),2),"")
A20: 12 | B20: =BIODATA!B35 -> 0 | C20: =BIODATA!C35 -> 0 | D20: =BIODATA!D35 -> KRISNA DWI PUTRA | E20: =BIODATA!H35 -> L | F20: =BIODATA!E35 -> X TKR 1 | G20: 89 | L20: =AVERAGE(G20:K20) -> 89 | M20: 99 | R20: =AVERAGE(M20:Q20) -> 99 | S20: 80 | X20: =AVERAGE(S20:W20) -> 80 | Y20: 87 | AC20: =AVERAGE(Y20:AB20) -> 87 | AD20: 91 | AH20: =AVERAGE(AD20:AG20) -> 91 | AI20: 80 | AK20: =AVERAGE(AI20:AJ20) -> 80 | AL20: 89 | AQ20: =AVERAGE(AL20:AP20) -> 89 | AR20: 79 | AW20: =AVERAGE(AR20:AV20) -> 79 | AX20: 85 | BC20: =AVERAGE(AX20:BB20) -> 85 | BD20: 86.333333 | BF20: =AVERAGE(BD20:BE20) -> 86.333333 | BG20: 82 | BI20: =AVERAGE(BG20:BH20) -> 82 | BJ20: 86.333333 | BL20: =AVERAGE(BJ20:BK20) -> 86.333333 | BP20: =AVERAGE(BM20:BO20) -> #DIV/0! | BT20: =AVERAGE(BQ20:BS20) -> #DIV/0! | BV20: =BU20 -> 0 | BZ20: =AVERAGE(BW20:BY20) -> #DIV/0! | CA20: =IFERROR(ROUND(AVERAGE(L20,R20,X20,AC20,AH20,AK20,AQ20,AW20,BC20,BF20,BI20,BL20,BP20,BT20,BV20,BZ20),2),"")
A21: 13 | B21: =BIODATA!B36 -> 0 | C21: =BIODATA!C36 -> 0 | D21: =BIODATA!D36 -> MARCELO JONAS NATRA ARSYAFIN | E21: =BIODATA!H36 -> L | F21: =BIODATA!E36 -> X TKR 1 | G21: 86 | L21: =AVERAGE(G21:K21) -> 86 | M21: 99 | R21: =AVERAGE(M21:Q21) -> 99 | S21: 80 | X21: =AVERAGE(S21:W21) -> 80 | Y21: 86 | AC21: =AVERAGE(Y21:AB21) -> 86 | AD21: 88 | AH21: =AVERAGE(AD21:AG21) -> 88 | AI21: 83 | AK21: =AVERAGE(AI21:AJ21) -> 83 | AL21: 86 | AQ21: =AVERAGE(AL21:AP21) -> 86 | AR21: 80 | AW21: =AVERAGE(AR21:AV21) -> 80 | AX21: 85 | BC21: =AVERAGE(AX21:BB21) -> 85 | BD21: 93.333333 | BF21: =AVERAGE(BD21:BE21) -> 93.333333 | BG21: 82 | BI21: =AVERAGE(BG21:BH21) -> 82 | BJ21: 93.333333 | BL21: =AVERAGE(BJ21:BK21) -> 93.333333 | BP21: =AVERAGE(BM21:BO21) -> #DIV/0! | BT21: =AVERAGE(BQ21:BS21) -> #DIV/0! | BV21: =BU21 -> 0 | BZ21: =AVERAGE(BW21:BY21) -> #DIV/0! | CA21: =IFERROR(ROUND(AVERAGE(L21,R21,X21,AC21,AH21,AK21,AQ21,AW21,BC21,BF21,BI21,BL21,BP21,BT21,BV21,BZ21),2),"")
A22: 14 | B22: =BIODATA!B37 -> 0 | C22: =BIODATA!C37 -> 0 | D22: =BIODATA!D37 -> MOCHAMAD DWI ADISATRIO | E22: =BIODATA!H37 -> L | F22: =BIODATA!E37 -> X TKR 1 | G22: 82 | L22: =AVERAGE(G22:K22) -> 82 | M22: 78 | R22: =AVERAGE(M22:Q22) -> 78 | S22: 80 | X22: =AVERAGE(S22:W22) -> 80 | Y22: 86 | AC22: =AVERAGE(Y22:AB22) -> 86 | AD22: 84 | AH22: =AVERAGE(AD22:AG22) -> 84 | AI22: 80 | AK22: =AVERAGE(AI22:AJ22) -> 80 | AL22: 82 | AQ22: =AVERAGE(AL22:AP22) -> 82 | AR22: 79 | AW22: =AVERAGE(AR22:AV22) -> 79 | AX22: 85 | BC22: =AVERAGE(AX22:BB22) -> 85 | BD22: 78 | BF22: =AVERAGE(BD22:BE22) -> 78 | BG22: 82 | BI22: =AVERAGE(BG22:BH22) -> 82 | BJ22: 78 | BL22: =AVERAGE(BJ22:BK22) -> 78 | BP22: =AVERAGE(BM22:BO22) -> #DIV/0! | BT22: =AVERAGE(BQ22:BS22) -> #DIV/0! | BV22: =BU22 -> 0 | BZ22: =AVERAGE(BW22:BY22) -> #DIV/0! | CA22: =IFERROR(ROUND(AVERAGE(L22,R22,X22,AC22,AH22,AK22,AQ22,AW22,BC22,BF22,BI22,BL22,BP22,BT22,BV22,BZ22),2),"")
A23: 15 | B23: =BIODATA!B38 -> 0 | C23: =BIODATA!C38 -> 0 | D23: =BIODATA!D38 -> MOHAMMAD BAMBANG SUBANDI | E23: =BIODATA!H38 -> L | F23: =BIODATA!E38 -> X TKR 1 | G23: 88 | L23: =AVERAGE(G23:K23) -> 88 | M23: 90 | R23: =AVERAGE(M23:Q23) -> 90 | S23: 80 | X23: =AVERAGE(S23:W23) -> 80 | Y23: 83 | AC23: =AVERAGE(Y23:AB23) -> 83 | AD23: 90 | AH23: =AVERAGE(AD23:AG23) -> 90 | AI23: 86 | AK23: =AVERAGE(AI23:AJ23) -> 86 | AL23: 88 | AQ23: =AVERAGE(AL23:AP23) -> 88 | AR23: 79 | AW23: =AVERAGE(AR23:AV23) -> 79 | AX23: 80 | BC23: =AVERAGE(AX23:BB23) -> 80 | BD23: 93 | BF23: =AVERAGE(BD23:BE23) -> 93 | BG23: 80 | BI23: =AVERAGE(BG23:BH23) -> 80 | BJ23: 93 | BL23: =AVERAGE(BJ23:BK23) -> 93 | BP23: =AVERAGE(BM23:BO23) -> #DIV/0! | BT23: =AVERAGE(BQ23:BS23) -> #DIV/0! | BV23: =BU23 -> 0 | BZ23: =AVERAGE(BW23:BY23) -> #DIV/0! | CA23: =IFERROR(ROUND(AVERAGE(L23,R23,X23,AC23,AH23,AK23,AQ23,AW23,BC23,BF23,BI23,BL23,BP23,BT23,BV23,BZ23),2),"")
A24: 16 | B24: =BIODATA!B39 -> 0 | C24: =BIODATA!C39 -> 0 | D24: =BIODATA!D39 -> MOHAMMAD ILHAM ABDULLOH | E24: =BIODATA!H39 -> L | F24: =BIODATA!E39 -> X TKR 1 | G24: 85 | L24: =AVERAGE(G24:K24) -> 85 | M24: 90 | R24: =AVERAGE(M24:Q24) -> 90 | S24: 82 | X24: =AVERAGE(S24:W24) -> 82 | Y24: 86 | AC24: =AVERAGE(Y24:AB24) -> 86 | AD24: 87 | AH24: =AVERAGE(AD24:AG24) -> 87 | AI24: 80 | AK24: =AVERAGE(AI24:AJ24) -> 80 | AL24: 85 | AQ24: =AVERAGE(AL24:AP24) -> 85 | AR24: 79 | AW24: =AVERAGE(AR24:AV24) -> 79 | AX24: 85 | BC24: =AVERAGE(AX24:BB24) -> 85 | BD24: 86.666667 | BF24: =AVERAGE(BD24:BE24) -> 86.666667 | BG24: 82 | BI24: =AVERAGE(BG24:BH24) -> 82 | BJ24: 86.666667 | BL24: =AVERAGE(BJ24:BK24) -> 86.666667 | BP24: =AVERAGE(BM24:BO24) -> #DIV/0! | BT24: =AVERAGE(BQ24:BS24) -> #DIV/0! | BV24: =BU24 -> 0 | BZ24: =AVERAGE(BW24:BY24) -> #DIV/0! | CA24: =IFERROR(ROUND(AVERAGE(L24,R24,X24,AC24,AH24,AK24,AQ24,AW24,BC24,BF24,BI24,BL24,BP24,BT24,BV24,BZ24),2),"")
A25: 17 | B25: =BIODATA!B40 -> 0 | C25: =BIODATA!C40 -> 0 | D25: =BIODATA!D40 -> MUHAMAD IQBAL LUCKY SAPUTRA | E25: =BIODATA!H40 -> L | F25: =BIODATA!E40 -> X TKR 1 | G25: 87 | L25: =AVERAGE(G25:K25) -> 87 | M25: 90 | R25: =AVERAGE(M25:Q25) -> 90 | S25: 81 | X25: =AVERAGE(S25:W25) -> 81 | Y25: 87 | AC25: =AVERAGE(Y25:AB25) -> 87 | AD25: 89 | AH25: =AVERAGE(AD25:AG25) -> 89 | AI25: 82 | AK25: =AVERAGE(AI25:AJ25) -> 82 | AL25: 87 | AQ25: =AVERAGE(AL25:AP25) -> 87 | AR25: 80 | AW25: =AVERAGE(AR25:AV25) -> 80 | AX25: 89 | BC25: =AVERAGE(AX25:BB25) -> 89 | BD25: 93.333333 | BF25: =AVERAGE(BD25:BE25) -> 93.333333 | BG25: 81 | BI25: =AVERAGE(BG25:BH25) -> 81 | BJ25: 93.333333 | BL25: =AVERAGE(BJ25:BK25) -> 93.333333 | BP25: =AVERAGE(BM25:BO25) -> #DIV/0! | BT25: =AVERAGE(BQ25:BS25) -> #DIV/0! | BV25: =BU25 -> 0 | BZ25: =AVERAGE(BW25:BY25) -> #DIV/0! | CA25: =IFERROR(ROUND(AVERAGE(L25,R25,X25,AC25,AH25,AK25,AQ25,AW25,BC25,BF25,BI25,BL25,BP25,BT25,BV25,BZ25),2),"")
A26: 18 | B26: =BIODATA!B41 -> 0 | C26: =BIODATA!C41 -> 0 | D26: =BIODATA!D41 -> MUHAMMAD ARDIAN CAHYA PRADANA | E26: =BIODATA!H41 -> L | F26: =BIODATA!E41 -> X TKR 1 | G26: 88 | L26: =AVERAGE(G26:K26) -> 88 | M26: 90 | R26: =AVERAGE(M26:Q26) -> 90 | S26: 80 | X26: =AVERAGE(S26:W26) -> 80 | Y26: 89 | AC26: =AVERAGE(Y26:AB26) -> 89 | AD26: 90 | AH26: =AVERAGE(AD26:AG26) -> 90 | AI26: 85 | AK26: =AVERAGE(AI26:AJ26) -> 85 | AL26: 88 | AQ26: =AVERAGE(AL26:AP26) -> 88 | AR26: 79 | AW26: =AVERAGE(AR26:AV26) -> 79 | AX26: 80 | BC26: =AVERAGE(AX26:BB26) -> 80 | BD26: 86.666667 | BF26: =AVERAGE(BD26:BE26) -> 86.666667 | BG26: 82 | BI26: =AVERAGE(BG26:BH26) -> 82 | BJ26: 86.666667 | BL26: =AVERAGE(BJ26:BK26) -> 86.666667 | BP26: =AVERAGE(BM26:BO26) -> #DIV/0! | BT26: =AVERAGE(BQ26:BS26) -> #DIV/0! | BV26: =BU26 -> 0 | BZ26: =AVERAGE(BW26:BY26) -> #DIV/0! | CA26: =IFERROR(ROUND(AVERAGE(L26,R26,X26,AC26,AH26,AK26,AQ26,AW26,BC26,BF26,BI26,BL26,BP26,BT26,BV26,BZ26),2),"")
A27: 19 | B27: =BIODATA!B42 -> 0 | C27: =BIODATA!C42 -> 0 | D27: =BIODATA!D42 -> MUHAMMAD MA'RUF ADI NUGRAHA | E27: =BIODATA!H42 -> L | F27: =BIODATA!E42 -> X TKR 1 | G27: 82 | L27: =AVERAGE(G27:K27) -> 82 | M27: 78 | R27: =AVERAGE(M27:Q27) -> 78 | S27: 80 | X27: =AVERAGE(S27:W27) -> 80 | Y27: 85 | AC27: =AVERAGE(Y27:AB27) -> 85 | AD27: 84 | AH27: =AVERAGE(AD27:AG27) -> 84 | AI27: 85 | AK27: =AVERAGE(AI27:AJ27) -> 85 | AL27: 82 | AQ27: =AVERAGE(AL27:AP27) -> 82 | AR27: 80 | AW27: =AVERAGE(AR27:AV27) -> 80 | AX27: 80 | BC27: =AVERAGE(AX27:BB27) -> 80 | BD27: 78 | BF27: =AVERAGE(BD27:BE27) -> 78 | BG27: 82 | BI27: =AVERAGE(BG27:BH27) -> 82 | BJ27: 78 | BL27: =AVERAGE(BJ27:BK27) -> 78 | BP27: =AVERAGE(BM27:BO27) -> #DIV/0! | BT27: =AVERAGE(BQ27:BS27) -> #DIV/0! | BV27: =BU27 -> 0 | BZ27: =AVERAGE(BW27:BY27) -> #DIV/0! | CA27: =IFERROR(ROUND(AVERAGE(L27,R27,X27,AC27,AH27,AK27,AQ27,AW27,BC27,BF27,BI27,BL27,BP27,BT27,BV27,BZ27),2),"")
A28: 20 | B28: =BIODATA!B43 -> 0 | C28: =BIODATA!C43 -> 0 | D28: =BIODATA!D43 -> MUHAMMAD RIDHO MAULUDDIN | E28: =BIODATA!H43 -> L | F28: =BIODATA!E43 -> X TKR 1 | G28: 83 | L28: =AVERAGE(G28:K28) -> 83 | M28: 99 | R28: =AVERAGE(M28:Q28) -> 99 | S28: 81 | X28: =AVERAGE(S28:W28) -> 81 | Y28: 86 | AC28: =AVERAGE(Y28:AB28) -> 86 | AD28: 85 | AH28: =AVERAGE(AD28:AG28) -> 85 | AI28: 85 | AK28: =AVERAGE(AI28:AJ28) -> 85 | AL28: 83 | AQ28: =AVERAGE(AL28:AP28) -> 83 | AR28: 70 | AW28: =AVERAGE(AR28:AV28) -> 70 | AX28: 80 | BC28: =AVERAGE(AX28:BB28) -> 80 | BD28: 78 | BF28: =AVERAGE(BD28:BE28) -> 78 | BG28: 82 | BI28: =AVERAGE(BG28:BH28) -> 82 | BJ28: 78 | BL28: =AVERAGE(BJ28:BK28) -> 78 | BP28: =AVERAGE(BM28:BO28) -> #DIV/0! | BT28: =AVERAGE(BQ28:BS28) -> #DIV/0! | BV28: =BU28 -> 0 | BZ28: =AVERAGE(BW28:BY28) -> #DIV/0! | CA28: =IFERROR(ROUND(AVERAGE(L28,R28,X28,AC28,AH28,AK28,AQ28,AW28,BC28,BF28,BI28,BL28,BP28,BT28,BV28,BZ28),2),"")
A29: 21 | B29: =BIODATA!B44 -> 0 | C29: =BIODATA!C44 -> 0 | D29: =BIODATA!D44 -> MUKHAMMAD ILHAM WIDIANTO | E29: =BIODATA!H44 -> L | F29: =BIODATA!E44 -> X TKR 1 | G29: 83 | L29: =AVERAGE(G29:K29) -> 83 | M29: 79 | R29: =AVERAGE(M29:Q29) -> 79 | S29: 82 | X29: =AVERAGE(S29:W29) -> 82 | Y29: 87 | AC29: =AVERAGE(Y29:AB29) -> 87 | AD29: 85 | AH29: =AVERAGE(AD29:AG29) -> 85 | AI29: 90 | AK29: =AVERAGE(AI29:AJ29) -> 90 | AL29: 83 | AQ29: =AVERAGE(AL29:AP29) -> 83 | AR29: 0 | AW29: =AVERAGE(AR29:AV29) -> 0 | AX29: 78 | BC29: =AVERAGE(AX29:BB29) -> 78 | BD29: 78 | BF29: =AVERAGE(BD29:BE29) -> 78 | BG29: 80 | BI29: =AVERAGE(BG29:BH29) -> 80 | BJ29: 78 | BL29: =AVERAGE(BJ29:BK29) -> 78 | BP29: =AVERAGE(BM29:BO29) -> #DIV/0! | BT29: =AVERAGE(BQ29:BS29) -> #DIV/0! | BV29: =BU29 -> 0 | BZ29: =AVERAGE(BW29:BY29) -> #DIV/0! | CA29: =IFERROR(ROUND(AVERAGE(L29,R29,X29,AC29,AH29,AK29,AQ29,AW29,BC29,BF29,BI29,BL29,BP29,BT29,BV29,BZ29),2),"")
A30: 22 | B30: =BIODATA!B45 -> 0 | C30: =BIODATA!C45 -> 0 | D30: =BIODATA!D45 -> PANDU WAHYUDA ARIS HERMAWAN | E30: =BIODATA!H45 -> L | F30: =BIODATA!E45 -> X TKR 1 | G30: 90 | L30: =AVERAGE(G30:K30) -> 90 | M30: 99 | R30: =AVERAGE(M30:Q30) -> 99 | S30: 81 | X30: =AVERAGE(S30:W30) -> 81 | Y30: 85 | AC30: =AVERAGE(Y30:AB30) -> 85 | AD30: 92 | AH30: =AVERAGE(AD30:AG30) -> 92 | AI30: 95 | AK30: =AVERAGE(AI30:AJ30) -> 95 | AL30: 90 | AQ30: =AVERAGE(AL30:AP30) -> 90 | AR30: 80 | AW30: =AVERAGE(AR30:AV30) -> 80 | AX30: 89 | BC30: =AVERAGE(AX30:BB30) -> 89 | BD30: 93.333333 | BF30: =AVERAGE(BD30:BE30) -> 93.333333 | BG30: 81 | BI30: =AVERAGE(BG30:BH30) -> 81 | BJ30: 93.333333 | BL30: =AVERAGE(BJ30:BK30) -> 93.333333 | BP30: =AVERAGE(BM30:BO30) -> #DIV/0! | BT30: =AVERAGE(BQ30:BS30) -> #DIV/0! | BV30: =BU30 -> 0 | BZ30: =AVERAGE(BW30:BY30) -> #DIV/0! | CA30: =IFERROR(ROUND(AVERAGE(L30,R30,X30,AC30,AH30,AK30,AQ30,AW30,BC30,BF30,BI30,BL30,BP30,BT30,BV30,BZ30),2),"")
A31: 23 | B31: =BIODATA!B46 -> 0 | C31: =BIODATA!C46 -> 0 | D31: =BIODATA!D46 -> PUTRA DWI REVANO | E31: =BIODATA!H46 -> L | F31: =BIODATA!E46 -> X TKR 1 | G31: 79 | L31: =AVERAGE(G31:K31) -> 79 | M31: 78 | R31: =AVERAGE(M31:Q31) -> 78 | S31: 81 | X31: =AVERAGE(S31:W31) -> 81 | Y31: 86 | AC31: =AVERAGE(Y31:AB31) -> 86 | AD31: 81 | AH31: =AVERAGE(AD31:AG31) -> 81 | AI31: 80 | AK31: =AVERAGE(AI31:AJ31) -> 80 | AL31: 79 | AQ31: =AVERAGE(AL31:AP31) -> 79 | AR31: 80 | AW31: =AVERAGE(AR31:AV31) -> 80 | AX31: 80 | BC31: =AVERAGE(AX31:BB31) -> 80 | BD31: 78 | BF31: =AVERAGE(BD31:BE31) -> 78 | BG31: 80 | BI31: =AVERAGE(BG31:BH31) -> 80 | BJ31: 78 | BL31: =AVERAGE(BJ31:BK31) -> 78 | BP31: =AVERAGE(BM31:BO31) -> #DIV/0! | BT31: =AVERAGE(BQ31:BS31) -> #DIV/0! | BV31: =BU31 -> 0 | BZ31: =AVERAGE(BW31:BY31) -> #DIV/0! | CA31: =IFERROR(ROUND(AVERAGE(L31,R31,X31,AC31,AH31,AK31,AQ31,AW31,BC31,BF31,BI31,BL31,BP31,BT31,BV31,BZ31),2),"")
... A40: 32 | B40: =BIODATA!B55 -> 0 | C40: =BIODATA!C55 -> 0 | D40: =BIODATA!D55 -> ZAKKI FAJAR ANANTA | E40: =BIODATA!H55 -> L | F40: =BIODATA!E55 -> X TKR 1 | G40: 80 | L40: =AVERAGE(G40:K40) -> 80 | M40: 78 | R40: =AVERAGE(M40:Q40) -> 78 | S40: 82 | X40: =AVERAGE(S40:W40) -> 82 | Y40: 88 | AC40: =AVERAGE(Y40:AB40) -> 88 | AD40: 82 | AH40: =AVERAGE(AD40:AG40) -> 82 | AI40: 85 | AK40: =AVERAGE(AI40:AJ40) -> 85 | AL40: 80 | AQ40: =AVERAGE(AL40:AP40) -> 80 | AR40: 79 | AW40: =AVERAGE(AR40:AV40) -> 79 | AX40: 78 | BC40: =AVERAGE(AX40:BB40) -> 78 | BD40: 78 | BF40: =AVERAGE(BD40:BE40) -> 78 | BG40: 82 | BI40: =AVERAGE(BG40:BH40) -> 82 | BJ40: 78 | BL40: =AVERAGE(BJ40:BK40) -> 78 | BP40: =AVERAGE(BM40:BO40) -> #DIV/0! | BT40: =AVERAGE(BQ40:BS40) -> #DIV/0! | BV40: =BU40 -> 0 | BZ40: =AVERAGE(BW40:BY40) -> #DIV/0! | CA40: =IFERROR(ROUND(AVERAGE(L40,R40,X40,AC40,AH40,AK40,AQ40,AW40,BC40,BF40,BI40,BL40,BP40,BT40,BV40,BZ40),2),"")
A41: 33 | B41: =BIODATA!B56 -> 0 | C41: =BIODATA!C56 -> 0 | D41: =BIODATA!D56 -> 0 | E41: =BIODATA!H56 -> L | F41: =BIODATA!E56 -> 0 | L41: =AVERAGE(G41:K41) -> #DIV/0! | R41: =AVERAGE(M41:Q41) -> #DIV/0! | X41: =AVERAGE(S41:W41) -> #DIV/0! | AC41: =AVERAGE(Y41:AB41) -> #DIV/0! | AH41: =AVERAGE(AD41:AG41) -> #DIV/0! | AK41: =AVERAGE(AI41:AJ41) -> #DIV/0! | AQ41: =AVERAGE(AL41:AP41) -> #DIV/0! | AW41: =AVERAGE(AR41:AV41) -> #DIV/0! | BC41: =AVERAGE(AX41:BB41) -> #DIV/0! | BF41: =AVERAGE(BD41:BE41) -> #DIV/0! | BI41: =AVERAGE(BG41:BH41) -> #DIV/0! | BL41: =AVERAGE(BJ41:BK41) -> #DIV/0! | BP41: =AVERAGE(BM41:BO41) -> #DIV/0! | BT41: =AVERAGE(BQ41:BS41) -> #DIV/0! | BV41: =BU41 -> 0 | BZ41: =AVERAGE(BW41:BY41) -> #DIV/0! | CA41: =IFERROR(ROUND(AVERAGE(L41,R41,X41,AC41,AH41,AK41,AQ41,AW41,BC41,BF41,BI41,BL41,BP41,BT41,BV41,BZ41),2),"")
A42: 34 | B42: =BIODATA!B57 -> 0 | C42: =BIODATA!C57 -> 0 | D42: =BIODATA!D57 -> 0 | E42: =BIODATA!H57 -> L | F42: =BIODATA!E57 -> 0 | L42: =AVERAGE(G42:K42) -> #DIV/0! | R42: =AVERAGE(M42:Q42) -> #DIV/0! | X42: =AVERAGE(S42:W42) -> #DIV/0! | AC42: =AVERAGE(Y42:AB42) -> #DIV/0! | AH42: =AVERAGE(AD42:AG42) -> #DIV/0! | AK42: =AVERAGE(AI42:AJ42) -> #DIV/0! | AQ42: =AVERAGE(AL42:AP42) -> #DIV/0! | AW42: =AVERAGE(AR42:AV42) -> #DIV/0! | BC42: =AVERAGE(AX42:BB42) -> #DIV/0! | BF42: =AVERAGE(BD42:BE42) -> #DIV/0! | BI42: =AVERAGE(BG42:BH42) -> #DIV/0! | BL42: =AVERAGE(BJ42:BK42) -> #DIV/0! | BP42: =AVERAGE(BM42:BO42) -> #DIV/0! | BT42: =AVERAGE(BQ42:BS42) -> #DIV/0! | BV42: =BU42 -> 0 | BZ42: =AVERAGE(BW42:BY42) -> #DIV/0! | CA42: =IFERROR(ROUND(AVERAGE(L42,R42,X42,AC42,AH42,AK42,AQ42,AW42,BC42,BF42,BI42,BL42,BP42,BT42,BV42,BZ42),2),"")
A43: 35 | B43: =BIODATA!B58 -> 0 | C43: =BIODATA!C58 -> 0 | D43: =BIODATA!D58 -> 0 | E43: =BIODATA!H58 -> L | F43: =BIODATA!E58 -> 0 | L43: =AVERAGE(G43:K43) -> #DIV/0! | R43: =AVERAGE(M43:Q43) -> #DIV/0! | X43: =AVERAGE(S43:W43) -> #DIV/0! | AC43: =AVERAGE(Y43:AB43) -> #DIV/0! | AH43: =AVERAGE(AD43:AG43) -> #DIV/0! | AK43: =AVERAGE(AI43:AJ43) -> #DIV/0! | AQ43: =AVERAGE(AL43:AP43) -> #DIV/0! | AW43: =AVERAGE(AR43:AV43) -> #DIV/0! | BC43: =AVERAGE(AX43:BB43) -> #DIV/0! | BF43: =AVERAGE(BD43:BE43) -> #DIV/0! | BI43: =AVERAGE(BG43:BH43) -> #DIV/0! | BL43: =AVERAGE(BJ43:BK43) -> #DIV/0! | BP43: =AVERAGE(BM43:BO43) -> #DIV/0! | BT43: =AVERAGE(BQ43:BS43) -> #DIV/0! | BV43: =BU43 -> 0 | BZ43: =AVERAGE(BW43:BY43) -> #DIV/0! | CA43: =IFERROR(ROUND(AVERAGE(L43,R43,X43,AC43,AH43,AK43,AQ43,AW43,BC43,BF43,BI43,BL43,BP43,BT43,BV43,BZ43),2),"")
A44: 36 | B44: =BIODATA!B59 -> 0 | C44: =BIODATA!C59 -> 0 | D44: =BIODATA!D59 -> 0 | E44: =BIODATA!H59 -> L | F44: =BIODATA!E59 -> 0 | L44: =AVERAGE(G44:K44) -> #DIV/0! | R44: =AVERAGE(M44:Q44) -> #DIV/0! | X44: =AVERAGE(S44:W44) -> #DIV/0! | AC44: =AVERAGE(Y44:AB44) -> #DIV/0! | AH44: =AVERAGE(AD44:AG44) -> #DIV/0! | AK44: =AVERAGE(AI44:AJ44) -> #DIV/0! | AQ44: =AVERAGE(AL44:AP44) -> #DIV/0! | AW44: =AVERAGE(AR44:AV44) -> #DIV/0! | BC44: =AVERAGE(AX44:BB44) -> #DIV/0! | BF44: =AVERAGE(BD44:BE44) -> #DIV/0! | BI44: =AVERAGE(BG44:BH44) -> #DIV/0! | BL44: =AVERAGE(BJ44:BK44) -> #DIV/0! | BP44: =AVERAGE(BM44:BO44) -> #DIV/0! | BT44: =AVERAGE(BQ44:BS44) -> #DIV/0! | BV44: =BU44 -> 0 | BZ44: =AVERAGE(BW44:BY44) -> #DIV/0! | CA44: =IFERROR(ROUND(AVERAGE(L44,R44,X44,AC44,AH44,AK44,AQ44,AW44,BC44,BF44,BI44,BL44,BP44,BT44,BV44,BZ44),2),"")
A45: 37 | B45: =BIODATA!B60 -> 0 | C45: =BIODATA!C60 -> 0 | D45: =BIODATA!D60 -> 0 | E45: =BIODATA!H60 -> L | F45: =BIODATA!E60 -> 0 | L45: =AVERAGE(G45:K45) -> #DIV/0! | R45: =AVERAGE(M45:Q45) -> #DIV/0! | X45: =AVERAGE(S45:W45) -> #DIV/0! | AC45: =AVERAGE(Y45:AB45) -> #DIV/0! | AH45: =AVERAGE(AD45:AG45) -> #DIV/0! | AK45: =AVERAGE(AI45:AJ45) -> #DIV/0! | AQ45: =AVERAGE(AL45:AP45) -> #DIV/0! | AW45: =AVERAGE(AR45:AV45) -> #DIV/0! | BC45: =AVERAGE(AX45:BB45) -> #DIV/0! | BF45: =AVERAGE(BD45:BE45) -> #DIV/0! | BI45: =AVERAGE(BG45:BH45) -> #DIV/0! | BL45: =AVERAGE(BJ45:BK45) -> #DIV/0! | BP45: =AVERAGE(BM45:BO45) -> #DIV/0! | BT45: =AVERAGE(BQ45:BS45) -> #DIV/0! | BV45: =BU45 -> 0 | BZ45: =AVERAGE(BW45:BY45) -> #DIV/0! | CA45: =IFERROR(ROUND(AVERAGE(L45,R45,X45,AC45,AH45,AK45,AQ45,AW45,BC45,BF45,BI45,BL45,BP45,BT45,BV45,BZ45),2),"")
A46: 38 | B46: =BIODATA!B61 -> 0 | C46: =BIODATA!C61 -> 0 | D46: =BIODATA!D61 -> 0 | E46: =BIODATA!H61 -> L | F46: =BIODATA!E61 -> 0 | L46: =AVERAGE(G46:K46) -> #DIV/0! | R46: =AVERAGE(M46:Q46) -> #DIV/0! | X46: =AVERAGE(S46:W46) -> #DIV/0! | AC46: =AVERAGE(Y46:AB46) -> #DIV/0! | AH46: =AVERAGE(AD46:AG46) -> #DIV/0! | AK46: =AVERAGE(AI46:AJ46) -> #DIV/0! | AQ46: =AVERAGE(AL46:AP46) -> #DIV/0! | AW46: =AVERAGE(AR46:AV46) -> #DIV/0! | BC46: =AVERAGE(AX46:BB46) -> #DIV/0! | BF46: =AVERAGE(BD46:BE46) -> #DIV/0! | BI46: =AVERAGE(BG46:BH46) -> #DIV/0! | BL46: =AVERAGE(BJ46:BK46) -> #DIV/0! | BP46: =AVERAGE(BM46:BO46) -> #DIV/0! | BT46: =AVERAGE(BQ46:BS46) -> #DIV/0! | BV46: =BU46 -> 0 | BZ46: =AVERAGE(BW46:BY46) -> #DIV/0! | CA46: =IFERROR(ROUND(AVERAGE(L46,R46,X46,AC46,AH46,AK46,AQ46,AW46,BC46,BF46,BI46,BL46,BP46,BT46,BV46,BZ46),2),"")
A47: 39 | B47: =BIODATA!B62 -> 0 | C47: =BIODATA!C62 -> 0 | D47: =BIODATA!D62 -> 0 | E47: =BIODATA!H62 -> L | F47: =BIODATA!E62 -> 0 | L47: =AVERAGE(G47:K47) -> #DIV/0! | R47: =AVERAGE(M47:Q47) -> #DIV/0! | X47: =AVERAGE(S47:W47) -> #DIV/0! | AC47: =AVERAGE(Y47:AB47) -> #DIV/0! | AH47: =AVERAGE(AD47:AG47) -> #DIV/0! | AK47: =AVERAGE(AI47:AJ47) -> #DIV/0! | AQ47: =AVERAGE(AL47:AP47) -> #DIV/0! | AW47: =AVERAGE(AR47:AV47) -> #DIV/0! | BC47: =AVERAGE(AX47:BB47) -> #DIV/0! | BF47: =AVERAGE(BD47:BE47) -> #DIV/0! | BI47: =AVERAGE(BG47:BH47) -> #DIV/0! | BL47: =AVERAGE(BJ47:BK47) -> #DIV/0! | BP47: =AVERAGE(BM47:BO47) -> #DIV/0! | BT47: =AVERAGE(BQ47:BS47) -> #DIV/0! | BV47: =BU47 -> 0 | BZ47: =AVERAGE(BW47:BY47) -> #DIV/0! | CA47: =IFERROR(ROUND(AVERAGE(L47,R47,X47,AC47,AH47,AK47,AQ47,AW47,BC47,BF47,BI47,BL47,BP47,BT47,BV47,BZ47),2),"")
A48: 40 | B48: =BIODATA!B63 -> 0 | C48: =BIODATA!C63 -> 0 | D48: =BIODATA!D63 -> 0 | E48: =BIODATA!H63 -> L | F48: =BIODATA!E63 -> 0 | L48: =AVERAGE(G48:K48) -> #DIV/0! | R48: =AVERAGE(M48:Q48) -> #DIV/0! | X48: =AVERAGE(S48:W48) -> #DIV/0! | AC48: =AVERAGE(Y48:AB48) -> #DIV/0! | AH48: =AVERAGE(AD48:AG48) -> #DIV/0! | AK48: =AVERAGE(AI48:AJ48) -> #DIV/0! | AQ48: =AVERAGE(AL48:AP48) -> #DIV/0! | AW48: =AVERAGE(AR48:AV48) -> #DIV/0! | BC48: =AVERAGE(AX48:BB48) -> #DIV/0! | BF48: =AVERAGE(BD48:BE48) -> #DIV/0! | BI48: =AVERAGE(BG48:BH48) -> #DIV/0! | BL48: =AVERAGE(BJ48:BK48) -> #DIV/0! | BP48: =AVERAGE(BM48:BO48) -> #DIV/0! | BT48: =AVERAGE(BQ48:BS48) -> #DIV/0! | BV48: =BU48 -> 0 | BZ48: =AVERAGE(BW48:BY48) -> #DIV/0! | CA48: =IFERROR(ROUND(AVERAGE(L48,R48,X48,AC48,AH48,AK48,AQ48,AW48,BC48,BF48,BI48,BL48,BP48,BT48,BV48,BZ48),2),"")
A49: NILAI RATA -RATA | G49: =AVERAGE(G9:G48) -> 84.645161 | H49: =AVERAGE(H9:H48) -> #DIV/0! | I49: =AVERAGE(I9:I48) -> #DIV/0! | J49: =AVERAGE(J9:J48) -> #DIV/0! | K49: =AVERAGE(K9:K48) -> #DIV/0! | L49: =AVERAGE(L9:L48) -> #DIV/0! | M49: =AVERAGE(M9:M48) -> 84.71875 | N49: =AVERAGE(N9:N48) -> #DIV/0! | ... CA49: =AVERAGE(CA9:CA48) -> #DIV/0!
A50: NILAI MAKSIMUM | G50: =MAX(G9:G48) -> 90 | H50: =MAX(H9:H48) -> 0 | I50: =MAX(I9:I48) -> 0 | J50: =MAX(J9:J48) -> 0 | K50: =MAX(K9:K48) -> 0 | L50: =MAX(L9:L48) -> #DIV/0! | M50: =MAX(M9:M48) -> 99 | N50: =MAX(N9:N48) -> 0 | ... CA50: =MAX(CA9:CA48) -> 0
...

Sheet PSAJ
A1: REKAPITULASI HASIL PENILAIAN SUMATIF AKHIR JENJANG KELAS XII
A2: =BIODATA!D7 & " - TAHUN AJARAN 2025 / 2026" -> SMKS PACET - TAHUN AJARAN 2025 / 2026
A5: NO | B5: NIS | C5: NISN | D5: Nama | E5: KELAS | F5: PA_BP | G5: P.PANCA | H5: BINA | I5: PJOK | J5: SEJ | K5: SEBUD | L5: BADER | M5: MAT | N5: BING | O5: INFOR | P5: IPAS | Q5: DDP | R5: UKK | S5: PKK | T5: PM | U5: RATA -RATA | V5: MAX | W5: MINIMUM
F7: 1 | G7: 2 | H7: 3 | I7: 4 | J7: 5 | K7: 6 | L7: 7 | M7: 8 | N7: 9 | O7: 10 | P7: 11 | Q7: 12 | R7: 13 | S7: 14 | T7: 15
A8: 1 | B8: =RR!B9 -> 0 | C8: =RR!C9 -> 0 | D8: =RR!D9 -> ABIL QOSHIM HAMDI | E8: =RR!F9 -> X TKR 1 | F8: 86 | G8: 80 | H8: 80 | I8: 85 | J8: 83 | K8: 82 | L8: 85 | M8: 80 | N8: 85 | O8: 82 | P8: 82 | Q8: 80 | R8: 85 | S8: 80 | T8: 80 | U8: =IFERROR(ROUND(AVERAGE(F8:T8),2),0) -> 82.33 | V8: =MAX(F8:T8) -> 86 | W8: =MIN(F8:T8) -> 80
A9: 2 | B9: =RR!B10 -> 0 | C9: =RR!C10 -> 0 | D9: =RR!D10 -> AHMA SELGI NUR SA'BAN | E9: =RR!F10 -> X TKR 1 | F9: 80 | G9: 81 | H9: 81 | I9: 81 | J9: 80 | K9: 80 | L9: 81 | M9: 80 | N9: 80 | O9: 80 | P9: 79 | Q9: 81 | R9: 84 | S9: 81 | T9: 81 | U9: =IFERROR(ROUND(AVERAGE(F9:T9),2),0) -> 80.67 | V9: =MAX(F9:T9) -> 84 | W9: =MIN(F9:T9) -> 79
A10: 3 | B10: =RR!B11 -> 0 | C10: =RR!C11 -> 0 | D10: =RR!D11 -> AHMAD ISOMUDDIN KHADIIQ | E10: =RR!F11 -> X TKR 1 | F10: 81 | G10: 80 | H10: 78 | I10: 80 | J10: 80 | K10: 82 | L10: 80 | M10: 87 | N10: 80 | O10: 83 | P10: 79 | Q10: 87 | R10: 87 | S10: 87 | T10: 87 | U10: =IFERROR(ROUND(AVERAGE(F10:T10),2),0) -> 82.53 | V10: =MAX(F10:T10) -> 87 | W10: =MIN(F10:T10) -> 78
A11: 4 | B11: =RR!B12 -> 0 | C11: =RR!C12 -> 0 | D11: =RR!D12 -> AHMAD VERNANDO ZAKARIA | E11: =RR!F12 -> X TKR 1 | F11: 99 | G11: 89 | H11: 88 | I11: 90 | J11: 94 | K11: 91 | L11: 90 | M11: 91 | N11: 90 | O11: 90 | P11: 93 | Q11: 90 | R11: 90 | S11: 91 | T11: 91 | U11: =IFERROR(ROUND(AVERAGE(F11:T11),2),0) -> 91.13 | V11: =MAX(F11:T11) -> 99 | W11: =MIN(F11:T11) -> 88
A12: 5 | B12: =RR!B13 -> 0 | C12: =RR!C13 -> 0 | D12: =RR!D13 -> ALVAREZA SETIA ANGGARA | E12: =RR!F13 -> X TKR 1 | F12: 85 | G12: 85 | H12: 78 | I12: 80 | J12: 85 | K12: 81 | L12: 80 | M12: 82 | N12: 80 | O12: 81 | P12: 84 | Q12: 82 | R12: 84 | S12: 82 | T12: 82 | U12: =IFERROR(ROUND(AVERAGE(F12:T12),2),0) -> 82.07 | V12: =MAX(F12:T12) -> 85 | W12: =MIN(F12:T12) -> 78
A13: 6 | B13: =RR!B14 -> 0 | C13: =RR!C14 -> 0 | D13: =RR!D14 -> ARSYAD ADITIA WIYONO | E13: =RR!F14 -> X TKR 1 | F13: 78 | G13: 80 | H13: 81 | I13: 80 | J13: 79 | K13: 79 | L13: 80 | M13: 78 | N13: 78 | O13: 78 | P13: 78 | Q13: 81 | R13: 80 | S13: 80 | T13: 80 | U13: =IFERROR(ROUND(AVERAGE(F13:T13),2),0) -> 79.33 | V13: =MAX(F13:T13) -> 81 | W13: =MIN(F13:T13) -> 78
A14: 7 | B14: =RR!B15 -> 0 | C14: =RR!C15 -> 0 | D14: =RR!D15 -> AULIYA ROHMAN AL BAIHAQI | E14: =RR!F15 -> X TKR 1 | F14: 78 | G14: 78 | H14: 82 | I14: 78 | J14: 78 | K14: 79 | L14: 78 | M14: 78 | N14: 78 | O14: 78 | P14: 77 | Q14: 82 | R14: 84 | S14: 78 | T14: 78 | U14: =IFERROR(ROUND(AVERAGE(F14:T14),2),0) -> 78.93 | V14: =MAX(F14:T14) -> 84 | W14: =MIN(F14:T14) -> 77
A15: 8 | B15: =RR!B16 -> 0 | C15: =RR!C16 -> 0 | D15: =RR!D16 -> AZIZUL HILMI FIRDAUS | E15: =RR!F16 -> X TKR 1 | F15: 78 | G15: 85 | H15: 86 | I15: 85 | J15: 81 | K15: 82 | L15: 85 | M15: 78 | N15: 78 | O15: 78 | P15: 80 | Q15: 86 | R15: 87 | S15: 85 | T15: 85 | U15: =IFERROR(ROUND(AVERAGE(F15:T15),2),0) -> 82.6 | V15: =MAX(F15:T15) -> 87 | W15: =MIN(F15:T15) -> 78
A16: 9 | B16: =RR!B17 -> 0 | C16: =RR!C17 -> 0 | D16: =RR!D17 -> DENILSEN ZAUSA OCTAVIANUS HERMANTO | E16: =RR!F17 -> X TKR 1 | F16: 82 | G16: 85 | H16: 86 | I16: 85 | J16: 83 | K16: 84 | L16: 85 | M16: 82 | N16: 82 | O16: 82 | P16: 82 | Q16: 86 | R16: 85 | S16: 85 | T16: 85 | U16: =IFERROR(ROUND(AVERAGE(F16:T16),2),0) -> 83.93 | V16: =MAX(F16:T16) -> 86 | W16: =MIN(F16:T16) -> 82
A17: 10 | B17: =RR!B18 -> 0 | C17: =RR!C18 -> 0 | D17: =RR!D18 -> FAJAR MAS'UD ALAMSYAH | E17: =RR!F18 -> X TKR 1 | F17: 86 | G17: 80 | H17: 80 | I17: 80 | J17: 83 | K17: 82 | L17: 80 | M17: 84 | N17: 80 | O17: 82 | P17: 82 | Q17: 84 | R17: 86 | S17: 84 | T17: 84 | U17: =IFERROR(ROUND(AVERAGE(F17:T17),2),0) -> 82.47 | V17: =MAX(F17:T17) -> 86 | W17: =MIN(F17:T17) -> 80
A18: 11 | B18: =RR!B19 -> 0 | C18: =RR!C19 -> 0 | D18: =RR!D19 -> JEFRI ALIF SUHENDRIK | E18: =RR!F19 -> X TKR 1 | F18: 82 | G18: 80 | H18: 83 | I18: 80 | J18: 81 | K18: 81 | L18: 80 | M18: 82 | N18: 82 | O18: 82 | P18: 80 | Q18: 83 | R18: 85 | S18: 80 | T18: 80 | U18: =IFERROR(ROUND(AVERAGE(F18:T18),2),0) -> 81.4 | V18: =MAX(F18:T18) -> 85 | W18: =MIN(F18:T18) -> 80
A19: 12 | B19: =RR!B20 -> 0 | C19: =RR!C20 -> 0 | D19: =RR!D20 -> KRISNA DWI PUTRA | E19: =RR!F20 -> X TKR 1 | F19: 88 | G19: 80 | H19: 83 | I19: 78 | J19: 84 | K19: 83 | L19: 78 | M19: 86 | N19: 78 | O19: 82 | P19: 83 | Q19: 86 | R19: 85 | S19: 86 | T19: 86 | U19: =IFERROR(ROUND(AVERAGE(F19:T19),2),0) -> 83.07 | V19: =MAX(F19:T19) -> 88 | W19: =MIN(F19:T19) -> 78
... A26: 19 | B26: =RR!B27 -> 0 | C26: =RR!C27 -> 0 | D26: =RR!D27 -> MUHAMMAD MA'RUF ADI NUGRAHA | E26: =RR!F27 -> X TKR 1 | F26: 78 | G26: 80 | H26: 83 | I26: 80 | J26: 79 | K26: 80 | L26: 80 | M26: 78 | N26: 78 | O26: 78 | P26: 78 | Q26: 83 | R26: 85 | S26: 80 | T26: 80 | U26: =IFERROR(ROUND(AVERAGE(F26:T26),2),0) -> 80 | V26: =MAX(F26:T26) -> 85 | W26: =MIN(F26:T26) -> 78
A27: 20 | B27: =RR!B28 -> 0 | C27: =RR!C28 -> 0 | D27: =RR!D28 -> MUHAMMAD RIDHO MAULUDDIN | E27: =RR!F28 -> X TKR 1 | U27: =IFERROR(ROUND(AVERAGE(F27:T27),2),0) -> 0 | V27: =MAX(F27:T27) -> 0 | W27: =MIN(F27:T27) -> 0
A28: 21 | B28: =RR!B29 -> 0 | C28: =RR!C29 -> 0 | D28: =RR!D29 -> MUKHAMMAD ILHAM WIDIANTO | E28: =RR!F29 -> X TKR 1 | U28: =IFERROR(ROUND(AVERAGE(F28:T28),2),0) -> 0 | V28: =MAX(F28:T28) -> 0 | W28: =MIN(F28:T28) -> 0
A29: 22 | B29: =RR!B30 -> 0 | C29: =RR!C30 -> 0 | D29: =RR!D30 -> PANDU WAHYUDA ARIS HERMAWAN | E29: =RR!F30 -> X TKR 1 | U29: =IFERROR(ROUND(AVERAGE(F29:T29),2),0) -> 0 | V29: =MAX(F29:T29) -> 0 | W29: =MIN(F29:T29) -> 0
A30: 23 | B30: =RR!B31 -> 0 | C30: =RR!C31 -> 0 | D30: =RR!D31 -> PUTRA DWI REVANO | E30: =RR!F31 -> X TKR 1 | U30: =IFERROR(ROUND(AVERAGE(F30:T30),2),0) -> 0 | V30: =MAX(F30:T30) -> 0 | W30: =MIN(F30:T30) -> 0
A31: 24 | B31: =RR!B32 -> 0 | C31: =RR!C32 -> 0 | D31: =RR!D32 -> RAFA ARDIANSYAH | E31: =RR!F32 -> X TKR 1 | U31: =IFERROR(ROUND(AVERAGE(F31:T31),2),0) -> 0 | V31: =MAX(F31:T31) -> 0 | W31: =MIN(F31:T31) -> 0
A32: 25 | B32: =RR!B33 -> 0 | C32: =RR!C33 -> 0 | D32: =RR!D33 -> RAGIL ROSYID NUR RIDHO | E32: =RR!F33 -> X TKR 1 | U32: =IFERROR(ROUND(AVERAGE(F32:T32),2),0) -> 0 | V32: =MAX(F32:T32) -> 0 | W32: =MIN(F32:T32) -> 0
A33: 26 | B33: =RR!B34 -> 0 | C33: =RR!C34 -> 0 | D33: =RR!D34 -> RANGGA SAHPUTRA ADI PRATAMA | E33: =RR!F34 -> X TKR 1 | U33: =IFERROR(ROUND(AVERAGE(F33:T33),2),0) -> 0 | V33: =MAX(F33:T33) -> 0 | W33: =MIN(F33:T33) -> 0
A34: 27 | B34: =RR!B35 -> 0 | C34: =RR!C35 -> 0 | D34: =RR!D35 -> RIFQI AL GHIFFARI ZAIDAN ZUHDI | E34: =RR!F35 -> X TKR 1 | U34: =IFERROR(ROUND(AVERAGE(F34:T34),2),0) -> 0 | V34: =MAX(F34:T34) -> 0 | W34: =MIN(F34:T34) -> 0
A35: 28 | B35: =RR!B36 -> 0 | C35: =RR!C36 -> 0 | D35: =RR!D36 -> SAPUTRA DWI ERLANGGA | E35: =RR!F36 -> X TKR 1 | U35: =IFERROR(ROUND(AVERAGE(F35:T35),2),0) -> 0 | V35: =MAX(F35:T35) -> 0 | W35: =MIN(F35:T35) -> 0
A36: 29 | B36: =RR!B37 -> 0 | C36: =RR!C37 -> 0 | D36: =RR!D37 -> SHANDY SETYA PRAYOGA | E36: =RR!F37 -> X TKR 1 | U36: =IFERROR(ROUND(AVERAGE(F36:T36),2),0) -> 0 | V36: =MAX(F36:T36) -> 0 | W36: =MIN(F36:T36) -> 0
A37: 30 | B37: =RR!B38 -> 0 | C37: =RR!C38 -> 0 | D37: =RR!D38 -> TIO ANDIKA EKO SAPUTRA | E37: =RR!F38 -> X TKR 1 | U37: =IFERROR(ROUND(AVERAGE(F37:T37),2),0) -> 0 | V37: =MAX(F37:T37) -> 0 | W37: =MIN(F37:T37) -> 0
A38: 31 | B38: =RR!B39 -> 0 | C38: =RR!C39 -> 0 | D38: =RR!D39 -> WIBHY EVAN RAMADHAN | E38: =RR!F39 -> X TKR 1 | U38: =IFERROR(ROUND(AVERAGE(F38:T38),2),0) -> 0 | V38: =MAX(F38:T38) -> 0 | W38: =MIN(F38:T38) -> 0
... A47: 40 | B47: =RR!B48 -> 0 | C47: =RR!C48 -> 0 | D47: =RR!D48 -> 0 | E47: =RR!F48 -> 0 | U47: =IFERROR(ROUND(AVERAGE(F47:T47),2),0) -> 0 | V47: =MAX(F47:T47) -> 0 | W47: =MIN(F47:T47) -> 0
A48: STATISTIK NILAI | D48: 91-100 | E48: INTERVAL NILAI | F48: =COUNTIFS($F$8:$F$47,">=91",$F$8:$F$47,"<=100") -> 1 | G48: =COUNTIFS(G$8:G$47,">=91",G$8:G$47,"<=100") -> 0 | H48: =COUNTIFS(H$8:H$47,">=91",H$8:H$47,"<=100") -> 0 | I48: =COUNTIFS(I$8:I$47,">=91",I$8:I$47,"<=100") -> 0 | J48: =COUNTIFS(J$8:J$47,">=91",J$8:J$47,"<=100") -> 1 | K48: =COUNTIFS(K$8:K$47,">=91",K$8:K$47,"<=100") -> 1 | L48: =COUNTIFS(L$8:L$47,">=91",L$8:L$47,"<=100") -> 0 | M48: =COUNTIFS(M$8:M$47,">=91",M$8:M$47,"<=100") -> 1 | N48: =COUNTIFS(N$8:N$47,">=91",N$8:N$47,"<=100") -> 0 | ... W48: =COUNTIFS(W$8:W$47,">=91",W$8:W$47,"<=100") -> 0
D49: 81-90 | F49: =COUNTIFS($F$8:$F$47,">=81",$F$8:$F$47,"<=90") -> 10 | G49: =COUNTIFS(G$8:G$47,">=81",G$8:G$47,"<=90") -> 6 | H49: =COUNTIFS(H$8:H$47,">=81",H$8:H$47,"<=90") -> 11 | I49: =COUNTIFS(I$8:I$47,">=81",I$8:I$47,"<=90") -> 6 | J49: =COUNTIFS(J$8:J$47,">=81",J$8:J$47,"<=90") -> 10 | K49: =COUNTIFS(K$8:K$47,">=81",K$8:K$47,"<=90") -> 13 | L49: =COUNTIFS(L$8:L$47,">=81",L$8:L$47,"<=90") -> 6 | M49: =COUNTIFS(M$8:M$47,">=81",M$8:M$47,"<=90") -> 10 | N49: =COUNTIFS(N$8:N$47,">=81",N$8:N$47,"<=90") -> 4 | ... W49: =COUNTIFS(W$8:W$47,">=81",W$8:W$47,"<=90") -> 2
D50: 71-80 | F50: =COUNTIFS(F$8:F$47,">=71",F$8:F$47,"<=80") -> 8 | G50: =COUNTIFS(G$8:G$47,">=71",G$8:G$47,"<=80") -> 13 | H50: =COUNTIFS(H$8:H$47,">=71",H$8:H$47,"<=80") -> 8 | I50: =COUNTIFS(I$8:I$47,">=71",I$8:I$47,"<=80") -> 13 | J50: =COUNTIFS(J$8:J$47,">=71",J$8:J$47,"<=80") -> 8 | K50: =COUNTIFS(K$8:K$47,">=71",K$8:K$47,"<=80") -> 5 | L50: =COUNTIFS(L$8:L$47,">=71",L$8:L$47,"<=80") -> 13 | M50: =COUNTIFS(M$8:M$47,">=71",M$8:M$47,"<=80") -> 8 | ... W50: =COUNTIFS(W$8:W$47,">=71",W$8:W$47,"<=80") -> 17
D51: 61-70 | F51: =COUNTIFS(F$8:F$47,">=61",F$8:F$47,"<=70") -> 0 | G51: =COUNTIFS(G$8:G$47,">=61",G$8:G$47,"<=70") -> 0 | H51: =COUNTIFS(H$8:H$47,">=61",H$8:H$47,"<=70") -> 0 | I51: =COUNTIFS(I$8:I$47,">=61",I$8:I$47,"<=70") -> 0 | J51: =COUNTIFS(J$8:J$47,">=61",J$8:J$47,"<=70") -> 0 | K51: =COUNTIFS(K$8:K$47,">=61",K$8:K$47,"<=70") -> 0 | L51: =COUNTIFS(L$8:L$47,">=61",L$8:L$47,"<=70") -> 0 | M51: =COUNTIFS(M$8:M$47,">=61",M$8:M$47,"<=70") -> 0 | ... W51: =COUNTIFS(W$8:W$47,">=61",W$8:W$47,"<=70") -> 0
D52: 51-60 | F52: =COUNTIFS(F$8:F$47,">=51",F$8:F$47,"<=60") -> 0 | G52: =COUNTIFS(G$8:G$47,">=51",G$8:G$47,"<=60") -> 0 | H52: =COUNTIFS(H$8:H$47,">=51",H$8:H$47,"<=60") -> 0 | I52: =COUNTIFS(I$8:I$47,">=51",I$8:I$47,"<=60") -> 0 | J52: =COUNTIFS(J$8:J$47,">=51",J$8:J$47,"<=60") -> 0 | K52: =COUNTIFS(K$8:K$47,">=51",K$8:K$47,"<=60") -> 0 | L52: =COUNTIFS(L$8:L$47,">=51",L$8:L$47,"<=60") -> 0 | M52: =COUNTIFS(M$8:M$47,">=51",M$8:M$47,"<=60") -> 0 | ... W52: =COUNTIFS(W$8:W$47,">=51",W$8:W$47,"<=60") -> 0
D53: 41-50 | F53: =COUNTIFS(F$8:F$47,">=41",F$8:F$47,"<=50") -> 0 | G53: =COUNTIFS(G$8:G$47,">=41",G$8:G$47,"<=50") -> 0 | H53: =COUNTIFS(H$8:H$47,">=41",H$8:H$47,"<=50") -> 0 | I53: =COUNTIFS(I$8:I$47,">=41",I$8:I$47,"<=50") -> 0 | J53: =COUNTIFS(J$8:J$47,">=41",J$8:J$47,"<=50") -> 0 | K53: =COUNTIFS(K$8:K$47,">=41",K$8:K$47,"<=50") -> 0 | L53: =COUNTIFS(L$8:L$47,">=41",L$8:L$47,"<=50") -> 0 | M53: =COUNTIFS(M$8:M$47,">=41",M$8:M$47,"<=50") -> 0 | ... W53: =COUNTIFS(W$8:W$47,">=41",W$8:W$47,"<=50") -> 0
D54: 31-40 | F54: =COUNTIFS(F$8:F$47,">=31",F$8:F$47,"<=40") -> 0 | G54: =COUNTIFS(G$8:G$47,">=31",G$8:G$47,"<=40") -> 0 | H54: =COUNTIFS(H$8:H$47,">=31",H$8:H$47,"<=40") -> 0 | I54: =COUNTIFS(I$8:I$47,">=31",I$8:I$47,"<=40") -> 0 | J54: =COUNTIFS(J$8:J$47,">=31",J$8:J$47,"<=40") -> 0 | K54: =COUNTIFS(K$8:K$47,">=31",K$8:K$47,"<=40") -> 0 | L54: =COUNTIFS(L$8:L$47,">=31",L$8:L$47,"<=40") -> 0 | M54: =COUNTIFS(M$8:M$47,">=31",M$8:M$47,"<=40") -> 0 | ... W54: =COUNTIFS(W$8:W$47,">=31",W$8:W$47,"<=40") -> 0
D55: 21-30 | F55: =COUNTIFS(F$8:F$47,">=21",F$8:F$47,"<=30") -> 0 | G55: =COUNTIFS(G$8:G$47,">=21",G$8:G$47,"<=30") -> 0 | H55: =COUNTIFS(H$8:H$47,">=21",H$8:H$47,"<=30") -> 0 | I55: =COUNTIFS(I$8:I$47,">=21",I$8:I$47,"<=30") -> 0 | J55: =COUNTIFS(J$8:J$47,">=21",J$8:J$47,"<=30") -> 0 | K55: =COUNTIFS(K$8:K$47,">=21",K$8:K$47,"<=30") -> 0 | L55: =COUNTIFS(L$8:L$47,">=21",L$8:L$47,"<=30") -> 0 | M55: =COUNTIFS(M$8:M$47,">=21",M$8:M$47,"<=30") -> 0 | ... W55: =COUNTIFS(W$8:W$47,">=21",W$8:W$47,"<=30") -> 0
D56: 46346 | F56: =COUNTIFS(F$8:F$47,">=11",F$8:F$47,"<=20") -> 0 | G56: =COUNTIFS(G$8:G$47,">=11",G$8:G$47,"<=20") -> 0 | H56: =COUNTIFS(H$8:H$47,">=11",H$8:H$47,"<=20") -> 0 | I56: =COUNTIFS(I$8:I$47,">=11",I$8:I$47,"<=20") -> 0 | J56: =COUNTIFS(J$8:J$47,">=11",J$8:J$47,"<=20") -> 0 | K56: =COUNTIFS(K$8:K$47,">=11",K$8:K$47,"<=20") -> 0 | L56: =COUNTIFS(L$8:L$47,">=11",L$8:L$47,"<=20") -> 0 | M56: =COUNTIFS(M$8:M$47,">=11",M$8:M$47,"<=20") -> 0 | ... W56: =COUNTIFS(W$8:W$47,">=11",W$8:W$47,"<=20") -> 0
D57: 46032 | F57: =COUNTIFS(F$8:F$47,">=1",F$8:F$47,"<=10") -> 0 | G57: =COUNTIFS(G$8:G$47,">=1",G$8:G$47,"<=10") -> 0 | H57: =COUNTIFS(H$8:H$47,">=1",H$8:H$47,"<=10") -> 0 | I57: =COUNTIFS(I$8:I$47,">=1",I$8:I$47,"<=10") -> 0 | J57: =COUNTIFS(J$8:J$47,">=1",J$8:J$47,"<=10") -> 0 | K57: =COUNTIFS(K$8:K$47,">=1",K$8:K$47,"<=10") -> 0 | L57: =COUNTIFS(L$8:L$47,">=1",L$8:L$47,"<=10") -> 0 | M57: =COUNTIFS(M$8:M$47,">=1",M$8:M$47,"<=10") -> 0 | ... W57: =COUNTIFS(W$8:W$47,">=1",W$8:W$47,"<=10") -> 0
...

Sheet DKN
A1: DAFTAR KUMPULAN NILAI SEKOLAH TINGKAT SMK
A2: TAHUN PELAJARAN 2025/2026 | AB2: FORMULA NSP | AC2: RAPOR | AD2: PSAJ
A3: Kab/Kota | D3: =": " & BIODATA!D6 -> : Kabupaten Mojokerto | V3: LEMBAR 1 : Sekolah Pelaksana | AC3: 50 | AD3: 50
A4: Nama Sekolah/Status | D4: =": " & BIODATA!D7 -> : SMKS PACET | V4: LEMBAR 2 : Pengambilan Blanko Ijazah | AB4: NSP = | AC4: =AC3 -> 50 | AD4: ="+" -> + | AE4: =AD3 -> 50
A5: Alamat/Nomor Telpon | D5: =": " & BIODATA!D8 -> : Jl. Raya Pacet-Trawas No. 21, Ds. Pacet,Kec. Pacet,Kab. Mojokerto | AD5: =AC4+AE4 -> 100
A6: Konsentrasi Keahlian | D6: =": " & BIODATA!D12 -> : Teknik Kendaraan Ringan | AB6: KRETERIA KELULUSAN
A7: No. Urut | B7: NIS | C7: NISN | D7: Nama Peserta | E7: L/P | F7: Mata Pelajaran | G7: KELOMPOK MAPEL UMUM | N7: KELOMPOK MAPEL KEJURUAN | W7: Jumlah | X7: Rata-Rata | Y7: Nilai karakter | Z7: Ket. (L/TL) | AB7: NILAI RATA -RATA RAPOR | AC7: 70
G8: Pend.Agama dan Budi Pekerti | H8: Pendidikan Pancasila | I8: B. Indonesia | J8: PJOK | K8: Sejarah | L8: Seni Budaya | M8: Mulok | N8: Matematika | O8: B. Inggris | P8: Informatika | Q8: Projek Ipas | R8: Dasar-2 Prog Keahlian | S8: Kons Keahlian | T8: PKK | U8: Praktek kerja Lapangan | V8: Mapel Pilihan | AB8: NILAI MINIMAL PSAJ | AC8: 65
AB9: MINIMAL NILAI RATA RATA NSP | AC9: 75
F11: Nilai | G11: 1 | H11: 2 | I11: 3 | J11: 4 | K11: 5 | L11: 6 | M11: 7 | N11: 8 | O11: 9 | P11: 10 | Q11: 11 | R11: 12 | S11: 13 | T11: 14 | U11: 15 | V11: 16 | W11: 17 | X11: 18 | Y11: 19 | Z11: 20
A12: =IF(MOD(ROW()-12,3)=0,INT((ROW()-12)/3)+1,"") -> 1 | B12: {=IF(MOD(ROW()-ROW($B$12),3)=0,INDEX(BIODATA!B:B,INT((ROW()-ROW($B$12))/3)+24),"")} -> 0 | C12: {=IF(MOD(ROW()-ROW($B$12),3)=0,INDEX(BIODATA!C:C,INT((ROW()-ROW($B$12))/3)+24),"")} -> 0 | D12: {=IF(MOD(ROW()-ROW($B$12),3)=0,INDEX(BIODATA!D:D,INT((ROW()-ROW($B$12))/3)+24),"")} -> ABIL QOSHIM HAMDI | E12: {=IF(MOD(ROW()-ROW($B$12),3)=0,INDEX(BIODATA!H:H,INT((ROW()-ROW($B$12))/3)+24),"")} -> L | F12: RR | G12: {=IF(MOD(ROW()-ROW($G$12),3)=0,INDEX(RR!L:L,INT((ROW()-ROW($G$12))/3)+9),"")} -> 78 | H12: {=IF(MOD(ROW()-ROW($H$12),3)=0,INDEX(RR!R:R,INT((ROW()-ROW($H$12))/3)+9),"")} -> 78 | I12: {=IF(MOD(ROW()-ROW($I$12),3)=0,INDEX(RR!X:X,INT((ROW()-ROW($I$12))/3)+9),"")} -> 80 | J12: {=IF(MOD(ROW()-ROW($I$12),3)=0,INDEX(RR!AC:AC,INT((ROW()-ROW($I$12))/3)+9),"")} -> 78 | K12: {=IF(MOD(ROW()-ROW($I$12),3)=0,INDEX(RR!AH:AH,INT((ROW()-ROW($I$12))/3)+9),"")} -> 80 | L12: {=IF(MOD(ROW()-ROW($I$12),3)=0,INDEX(RR!AK:AK,INT((ROW()-ROW($I$12))/3)+9),"")} -> 85 | M12: {=IF(MOD(ROW()-ROW($I$12),3)=0,INDEX(RR!AQ:AQ,INT((ROW()-ROW($I$12))/3)+9),"")} -> 78 | N12: {=IF(MOD(ROW()-ROW($I$12),3)=0,INDEX(RR!AW:AW,INT((ROW()-ROW($I$12))/3)+9),"")} -> 78 | O12: {=IF(MOD(ROW()-ROW($I$12),3)=0,INDEX(RR!BB:BB,INT((ROW()-ROW($I$12))/3)+9),"")} -> 0 | P12: {=IF(MOD(ROW()-ROW($I$12),3)=0,INDEX(RR!BF:BF,INT((ROW()-ROW($I$12))/3)+9),"")} -> 78 | Q12: {=IF(MOD(ROW()-ROW($I$12),3)=0,INDEX(RR!BI:BI,INT((ROW()-ROW($I$12))/3)+9),"")} -> 80 | R12: {=IF(MOD(ROW()-ROW($I$12),3)=0,INDEX(RR!BL:BL,INT((ROW()-ROW($I$12))/3)+9),"")} -> 78 | S12: {=IF(MOD(ROW()-ROW($I$12),3)=0,INDEX(RR!BP:BP,INT((ROW()-ROW($I$12))/3)+9),"")} -> #DIV/0! | T12: {=IF(MOD(ROW()-ROW($I$12),3)=0,INDEX(RR!BT:BT,INT((ROW()-ROW($I$12))/3)+9),"")} -> #DIV/0! | U12: {=IF(MOD(ROW()-ROW($I$12),3)=0,INDEX(RR!BV:BV,INT((ROW()-ROW($I$12))/3)+9),"")} -> 0 | V12: {=IF(MOD(ROW()-ROW($I$12),3)=0,INDEX(RR!BZ:BZ,INT((ROW()-ROW($I$12))/3)+9),"")} -> #DIV/0! | W12: =IF(MOD(ROW()-ROW($W$12),3)<>2,SUM(G12:V12),"") -> #DIV/0! | X12: =IF(MOD(ROW()-ROW($X$12),3)<>2,ROUND(W12/16,2),"") -> #DIV/0! | Z12: {=IF(MOD(ROW()-ROW($Z$12),3)=0,IF(INDEX(X:X,ROW()+2)>=$AC$9,"L","TL"),"")} -> #DIV/0!
A13: =IF(MOD(ROW()-12,3)=0,INT((ROW()-12)/3)+1,"") | B13: {=IF(MOD(ROW()-ROW($B$12),3)=0,INDEX(BIODATA!B:B,INT((ROW()-ROW($B$12))/3)+24),"")} | F13: PSAJ | G13: {=IF(MOD(ROW()-ROW($G$12),3)=1,INDEX(PSAJ!F:F,INT((ROW()-ROW($G$12))/3)+8),"")} -> 86 | H13: {=IF(MOD(ROW()-ROW($G$12),3)=1,INDEX(PSAJ!G:G,INT((ROW()-ROW($G$12))/3)+8),"")} -> 80 | I13: {=IF(MOD(ROW()-ROW($G$12),3)=1,INDEX(PSAJ!H:H,INT((ROW()-ROW($G$12))/3)+8),"")} -> 80 | J13: {=IF(MOD(ROW()-ROW($G$12),3)=1,INDEX(PSAJ!I:I,INT((ROW()-ROW($G$12))/3)+8),"")} -> 85 | K13: {=IF(MOD(ROW()-ROW($G$12),3)=1,INDEX(PSAJ!J:J,INT((ROW()-ROW($G$12))/3)+8),"")} -> 83 | L13: {=IF(MOD(ROW()-ROW($G$12),3)=1,INDEX(PSAJ!K:K,INT((ROW()-ROW($G$12))/3)+8),"")} -> 82 | M13: {=IF(MOD(ROW()-ROW($G$12),3)=1,INDEX(PSAJ!L:L,INT((ROW()-ROW($G$12))/3)+8),"")} -> 85 | N13: {=IF(MOD(ROW()-ROW($G$12),3)=1,INDEX(PSAJ!M:M,INT((ROW()-ROW($G$12))/3)+8),"")} -> 80 | O13: {=IF(MOD(ROW()-ROW($G$12),3)=1,INDEX(PSAJ!N:N,INT((ROW()-ROW($G$12))/3)+8),"")} -> 85 | P13: {=IF(MOD(ROW()-ROW($G$12),3)=1,INDEX(PSAJ!O:O,INT((ROW()-ROW($G$12))/3)+8),"")} -> 82 | Q13: {=IF(MOD(ROW()-ROW($G$12),3)=1,INDEX(PSAJ!P:P,INT((ROW()-ROW($G$12))/3)+8),"")} -> 82 | R13: {=IF(MOD(ROW()-ROW($G$12),3)=1,INDEX(PSAJ!Q:Q,INT((ROW()-ROW($G$12))/3)+8),"")} -> 80 | S13: {=IF(MOD(ROW()-ROW($G$12),3)=1,INDEX(PSAJ!R:R,INT((ROW()-ROW($G$12))/3)+8),"")} -> 85 | T13: {=IF(MOD(ROW()-ROW($G$12),3)=1,INDEX(PSAJ!S:S,INT((ROW()-ROW($G$12))/3)+8),"")} -> 80 | U13: 0 | V13: {=IF(MOD(ROW()-ROW($G$12),3)=1,INDEX(PSAJ!T:T,INT((ROW()-ROW($G$12))/3)+8),"")} -> 80 | W13: =IF(MOD(ROW()-ROW($W$12),3)<>2,SUM(G13:V13),"") -> 1235 | X13: =IF(MOD(ROW()-ROW($X$12),3)<>2,ROUND(W13/15,2),"") -> 82.33
F14: NSP | G14: =IF(MOD(ROW()-ROW($G$12),3)=2,((INDEX(G:G,ROW()-2)*$AC$4)+(INDEX(G:G,ROW()-1)*$AE$4))/$AD$5,"") -> 82 | H14: =IF(MOD(ROW()-ROW($G$12),3)=2,((INDEX(H:H,ROW()-2)*$AC$4)+(INDEX(H:H,ROW()-1)*$AE$4))/$AD$5,"") -> 79 | I14: =IF(MOD(ROW()-ROW($G$12),3)=2,((INDEX(I:I,ROW()-2)*$AC$4)+(INDEX(I:I,ROW()-1)*$AE$4))/$AD$5,"") -> 80 | J14: =IF(MOD(ROW()-ROW($G$12),3)=2,((INDEX(J:J,ROW()-2)*$AC$4)+(INDEX(J:J,ROW()-1)*$AE$4))/$AD$5,"") -> 81.5 | K14: =IF(MOD(ROW()-ROW($G$12),3)=2,((INDEX(K:K,ROW()-2)*$AC$4)+(INDEX(K:K,ROW()-1)*$AE$4))/$AD$5,"") -> 81.5 | L14: =IF(MOD(ROW()-ROW($G$12),3)=2,((INDEX(L:L,ROW()-2)*$AC$4)+(INDEX(L:L,ROW()-1)*$AE$4))/$AD$5,"") -> 83.5 | M14: =IF(MOD(ROW()-ROW($G$12),3)=2,((INDEX(M:M,ROW()-2)*$AC$4)+(INDEX(M:M,ROW()-1)*$AE$4))/$AD$5,"") -> 81.5 | N14: =IF(MOD(ROW()-ROW($G$12),3)=2,((INDEX(N:N,ROW()-2)*$AC$4)+(INDEX(N:N,ROW()-1)*$AE$4))/$AD$5,"") -> 79 | O14: =IF(MOD(ROW()-ROW($G$12),3)=2,((INDEX(O:O,ROW()-2)*$AC$4)+(INDEX(O:O,ROW()-1)*$AE$4))/$AD$5,"") -> 42.5 | P14: =IF(MOD(ROW()-ROW($G$12),3)=2,((INDEX(P:P,ROW()-2)*$AC$4)+(INDEX(P:P,ROW()-1)*$AE$4))/$AD$5,"") -> 80 | Q14: =IF(MOD(ROW()-ROW($G$12),3)=2,((INDEX(Q:Q,ROW()-2)*$AC$4)+(INDEX(Q:Q,ROW()-1)*$AE$4))/$AD$5,"") -> 81 | R14: =IF(MOD(ROW()-ROW($G$12),3)=2,((INDEX(R:R,ROW()-2)*$AC$4)+(INDEX(R:R,ROW()-1)*$AE$4))/$AD$5,"") -> 79 | S14: =IF(MOD(ROW()-ROW($G$12),3)=2,((INDEX(S:S,ROW()-2)*$AC$4)+(INDEX(S:S,ROW()-1)*$AE$4))/$AD$5,"") -> #DIV/0! | T14: =IF(MOD(ROW()-ROW($G$12),3)=2,((INDEX(T:T,ROW()-2)*$AC$4)+(INDEX(T:T,ROW()-1)*$AE$4))/$AD$5,"") -> #DIV/0! | U14: {=IF(MOD(ROW()-ROW($U$12),3)=2,N(INDEX(U:U,ROW()-2)),0)} -> 0 | V14: =IF(MOD(ROW()-ROW($G$12),3)=2,((INDEX(V:V,ROW()-2)*$AC$4)+(INDEX(V:V,ROW()-1)*$AE$4))/$AD$5,"") -> #DIV/0! | W14: =IF(MOD(ROW()-ROW($G$12),3)=2,((INDEX(W:W,ROW()-2)*$AC$4)+(INDEX(W:W,ROW()-1)*$AE$4))/$AD$5,"") -> #DIV/0! | X14: =IF(MOD(ROW()-ROW($G$12),3)=2,((INDEX(X:X,ROW()-2)*$AC$4)+(INDEX(X:X,ROW()-1)*$AE$4))/$AD$5,"") -> #DIV/0!
A15: =IF(MOD(ROW()-12,3)=0,INT((ROW()-12)/3)+1,"") -> 2 | B15: {=IF(MOD(ROW()-ROW($B$12),3)=0,INDEX(BIODATA!B:B,INT((ROW()-ROW($B$12))/3)+24),"")} -> 0 | C15: {=IF(MOD(ROW()-ROW($B$12),3)=0,INDEX(BIODATA!C:C,INT((ROW()-ROW($B$12))/3)+24),"")} -> 0 | D15: {=IF(MOD(ROW()-ROW($B$12),3)=0,INDEX(BIODATA!D:D,INT((ROW()-ROW($B$12))/3)+24),"")} -> AHMA SELGI NUR SA'BAN | E15: {=IF(MOD(ROW()-ROW($B$12),3)=0,INDEX(BIODATA!H:H,INT((ROW()-ROW($B$12))/3)+24),"")} -> L | F15: RR | G15: {=IF(MOD(ROW()-ROW($G$12),3)=0,INDEX(RR!L:L,INT((ROW()-ROW($G$12))/3)+9),"")} -> 85 | H15: {=IF(MOD(ROW()-ROW($H$12),3)=0,INDEX(RR!R:R,INT((ROW()-ROW($H$12))/3)+9),"")} -> 78 | I15: {=IF(MOD(ROW()-ROW($I$12),3)=0,INDEX(RR!X:X,INT((ROW()-ROW($I$12))/3)+9),"")} -> 80 | J15: {=IF(MOD(ROW()-ROW($I$12),3)=0,INDEX(RR!AC:AC,INT((ROW()-ROW($I$12))/3)+9),"")} -> 88 | K15: {=IF(MOD(ROW()-ROW($I$12),3)=0,INDEX(RR!AH:AH,INT((ROW()-ROW($I$12))/3)+9),"")} -> 87 | L15: {=IF(MOD(ROW()-ROW($I$12),3)=0,INDEX(RR!AK:AK,INT((ROW()-ROW($I$12))/3)+9),"")} -> 85 | M15: {=IF(MOD(ROW()-ROW($I$12),3)=0,INDEX(RR!AQ:AQ,INT((ROW()-ROW($I$12))/3)+9),"")} -> 85 | N15: {=IF(MOD(ROW()-ROW($I$12),3)=0,INDEX(RR!AW:AW,INT((ROW()-ROW($I$12))/3)+9),"")} -> 79 | O15: {=IF(MOD(ROW()-ROW($I$12),3)=0,INDEX(RR!BB:BB,INT((ROW()-ROW($I$12))/3)+9),"")} -> 0 | P15: {=IF(MOD(ROW()-ROW($I$12),3)=0,INDEX(RR!BF:BF,INT((ROW()-ROW($I$12))/3)+9),"")} -> 78 | Q15: {=IF(MOD(ROW()-ROW($I$12),3)=0,INDEX(RR!BI:BI,INT((ROW()-ROW($I$12))/3)+9),"")} -> 82 | R15: {=IF(MOD(ROW()-ROW($I$12),3)=0,INDEX(RR!BL:BL,INT((ROW()-ROW($I$12))/3)+9),"")} -> 78 | S15: {=IF(MOD(ROW()-ROW($I$12),3)=0,INDEX(RR!BP:BP,INT((ROW()-ROW($I$12))/3)+9),"")} -> #DIV/0! | T15: {=IF(MOD(ROW()-ROW($I$12),3)=0,INDEX(RR!BT:BT,INT((ROW()-ROW($I$12))/3)+9),"")} -> #DIV/0! | U15: {=IF(MOD(ROW()-ROW($I$12),3)=0,INDEX(RR!BV:BV,INT((ROW()-ROW($I$12))/3)+9),"")} -> 0 | V15: {=IF(MOD(ROW()-ROW($I$12),3)=0,INDEX(RR!BZ:BZ,INT((ROW()-ROW($I$12))/3)+9),"")} -> #DIV/0! | W15: =IF(MOD(ROW()-ROW($W$12),3)<>2,SUM(G15:V15),"") -> #DIV/0! | X15: =IF(MOD(ROW()-ROW($X$12),3)<>2,ROUND(W15/16,2),"") -> #DIV/0! | Z15: {=IF(MOD(ROW()-ROW($Z$12),3)=0,IF(INDEX(X:X,ROW()+2)>=$AC$9,"L","TL"),"")} -> #DIV/0!
A16: =IF(MOD(ROW()-12,3)=0,INT((ROW()-12)/3)+1,"") | B16: {=IF(MOD(ROW()-ROW($B$12),3)=0,INDEX(BIODATA!B:B,INT((ROW()-ROW($B$12))/3)+24),"")} | F16: PSAJ | G16: {=IF(MOD(ROW()-ROW($G$12),3)=1,INDEX(PSAJ!F:F,INT((ROW()-ROW($G$12))/3)+8),"")} -> 80 | H16: {=IF(MOD(ROW()-ROW($G$12),3)=1,INDEX(PSAJ!G:G,INT((ROW()-ROW($G$12))/3)+8),"")} -> 81 | I16: {=IF(MOD(ROW()-ROW($G$12),3)=1,INDEX(PSAJ!H:H,INT((ROW()-ROW($G$12))/3)+8),"")} -> 81 | J16: {=IF(MOD(ROW()-ROW($G$12),3)=1,INDEX(PSAJ!I:I,INT((ROW()-ROW($G$12))/3)+8),"")} -> 81 | K16: {=IF(MOD(ROW()-ROW($G$12),3)=1,INDEX(PSAJ!J:J,INT((ROW()-ROW($G$12))/3)+8),"")} -> 80 | L16: {=IF(MOD(ROW()-ROW($G$12),3)=1,INDEX(PSAJ!K:K,INT((ROW()-ROW($G$12))/3)+8),"")} -> 80 | M16: {=IF(MOD(ROW()-ROW($G$12),3)=1,INDEX(PSAJ!L:L,INT((ROW()-ROW($G$12))/3)+8),"")} -> 81 | N16: {=IF(MOD(ROW()-ROW($G$12),3)=1,INDEX(PSAJ!M:M,INT((ROW()-ROW($G$12))/3)+8),"")} -> 80 | O16: {=IF(MOD(ROW()-ROW($G$12),3)=1,INDEX(PSAJ!N:N,INT((ROW()-ROW($G$12))/3)+8),"")} -> 80 | P16: {=IF(MOD(ROW()-ROW($G$12),3)=1,INDEX(PSAJ!O:O,INT((ROW()-ROW($G$12))/3)+8),"")} -> 80 | Q16: {=IF(MOD(ROW()-ROW($G$12),3)=1,INDEX(PSAJ!P:P,INT((ROW()-ROW($G$12))/3)+8),"")} -> 79 | R16: {=IF(MOD(ROW()-ROW($G$12),3)=1,INDEX(PSAJ!Q:Q,INT((ROW()-ROW($G$12))/3)+8),"")} -> 81 | S16: {=IF(MOD(ROW()-ROW($G$12),3)=1,INDEX(PSAJ!R:R,INT((ROW()-ROW($G$12))/3)+8),"")} -> 84 | T16: {=IF(MOD(ROW()-ROW($G$12),3)=1,INDEX(PSAJ!S:S,INT((ROW()-ROW($G$12))/3)+8),"")} -> 81 | U16: 0 | V16: {=IF(MOD(ROW()-ROW($G$12),3)=1,INDEX(PSAJ!T:T,INT((ROW()-ROW($G$12))/3)+8),"")} -> 81 | W16: =IF(MOD(ROW()-ROW($W$12),3)<>2,SUM(G16:V16),"") -> 1210 | X16: =IF(MOD(ROW()-ROW($X$12),3)<>2,ROUND(W16/15,2),"") -> 80.67
